Workbook
Name badge_away: IFERROR(IF(TYPE(Teams!$B$2)=128,INDEX(TablaEquipos[Badge],MATCH(League!B1,TablaEquipos[Team],0)),""),"")
Name badge_home: IFERROR(IF(TYPE(Teams!$B$2)=128,INDEX(TablaEquipos[Badge],MATCH(League!XFD1,TablaEquipos[Team],0)),""),"")
Name badge_ko: IFERROR(IF(TYPE(Teams!$B$2)=128,INDEX(TablaEquipos[Badge],MATCH(KO!B1,TablaEquipos[Team],0)),""),"")
Name Equipo_local: League!$D$2:$D$145
Name Equipo_visitante: League!$K$2:$K$145
Name Ganador: League!$BF$2:$BF$145
Name Goles_local: League!$G$2:$G$145
Name Goles_visitante: League!$H$2:$H$145
Name Jornada: League!$A$2:$A$145
Name NombreEquipo: TablaEquipos[Team]
Name NombreEquipo: TablaEquipos[Team]
Name NombreEquipo: TablaEquipos[Team]
Name NombreEquipo: TablaEquipos[Team]

Sheet Home
B2: EXCEL CHAMPIONS LEAGUE 2026-2027
J6: Para acceder Click en | K6: 2
B7: =Idiomas!D8 -> Selecciona idioma -> | C7: Español | G7: =Idiomas!D6 -> Predictor Equipos | I7: Item | J7: Español | K7: Inglés
I8: Excel Europa League 2026-2027 | J8: 2 | K8: 2
I9: Excel Conference League 2026-2027 | J9: 2 | K9: 2
B10: =Idiomas!D18 -> Selecciona Horario -> | C10: España | G10: =Idiomas!D4 -> Introducir resultados Fase de Liga | I10: Excel Premier League 2026-2027 | J10: 0 | K10: 2
I11: Excel Championship 2026-2027 | J11: 0 | K11: 2
I12: Excel Liga 1ª Division 2026-2027 | J12: 2 | K12: 0
B13: =Idiomas!D43 -> Escribe tu nombre -> | C13: =Idiomas!D44 -> Nombre | G13: =Idiomas!D5 -> Introducir resultados Fase KO | I13: Excel Liga 2ª Division 2026-2027 | J13: 2 | K13: 0
I14: Excel Liga 1ª Federación 2026-2027 | J14: 2 | K14: 0
I15: Excel Liga F. 2026-2027 | J15: 2 | K15: 0
B16: =HYPERLINK(Idiomas!D11,Idiomas!D7) -> Si quieres organizar una porra con tu grupo puedes descargar el archivo para administrarla desde aquí. | I16: Excel Libertadores/Sudamericana 2026 | J16: 2 | K16: 0
I17: =Idiomas!D15 -> Excel Mundial Femenino 2027 | J17: 2 | K17: 2
I19: =HYPERLINK(Idiomas!D16,Idiomas!D15) -> Excel Mundial Femenino 2027
I23: © Miguel Angel Tejero. 2026 | J23: DONAR

Sheet Predictor
B1: =Idiomas!D365 -> Ronda | C1: =Idiomas!D364 -> Predice el equipo | E1: =Idiomas!D370 -> Rellenar antes del comienzo de la Champions | H1: Equipo | I1: CAUX1 | J1: CAUX2 | K1: CAUX3 | L1: CAUX4 | N1: Lista desplegable | R1: IDIOMA PARA PONER EL EL POOL
B2: =Idiomas!D356 -> Campeón | G2: =TablaEquipos[[#This Row],[Team]] -> AEK | H2: =C2 -> 0 | I2: =IF(COUNTIF($H$2:$H$37,G2)>=COUNTIF($G$2:$G$37,G2),"",G2) -> AEK | J2: =IF(I2<>"",ROWS($I$2:I2),"") -> 1 | K2: =IFERROR(SMALL($J$2:$J$37,ROWS($J$2:J2)),"") -> 1 | L2: {=IFERROR(INDEX($G$2:$G$37,K2),0)} -> AEK | N2: {=IFERROR(OFFSET($L$2,0,0,COUNTIF($L$2:$L$37,"<>0"),1),"")} -> AEK | P2: {=OFFSET($L$2,0,0,COUNTIF($L$2:$L$37,"<>0"),1)} -> AEK | R2: =+IFERROR(IFERROR(INDEX(Idiomas!$D$313:$D$348,MATCH(Predictor!C2,Idiomas!$G$313:$G$348,0)),INDEX(Idiomas!$D$313:$D$348,MATCH(Predictor!C2,Idiomas!$H$313:$H$348,0))),"")
B3: =Idiomas!D357 -> Final | E3: =Idiomas!D366 -> ·Selecciona para cada ronda el equipo o los equipos que crees que van a llegar hasta esa ronda. | G3: =TablaEquipos[[#This Row],[Team]] -> Arsenal | H3: =C3 -> 0 | I3: =IF(COUNTIF($H$2:$H$37,G3)>=COUNTIF($G$2:$G$37,G3),"",G3) -> Arsenal | J3: =IF(I3<>"",ROWS($I$2:I3),"") -> 2 | K3: =IFERROR(SMALL($J$2:$J$37,ROWS($J$2:J3)),"") -> 2 | L3: {=IFERROR(INDEX($G$2:$G$37,K3),0)} -> Arsenal | N3: Arsenal | P3: Arsenal | R3: =+IFERROR(IFERROR(INDEX(Idiomas!$D$313:$D$348,MATCH(Predictor!C3,Idiomas!$G$313:$G$348,0)),INDEX(Idiomas!$D$313:$D$348,MATCH(Predictor!C3,Idiomas!$H$313:$H$348,0))),"")
B4: =Idiomas!D358 -> Semifinales | G4: =TablaEquipos[[#This Row],[Team]] -> Aston Villa | H4: =C4 -> 0 | I4: =IF(COUNTIF($H$2:$H$37,G4)>=COUNTIF($G$2:$G$37,G4),"",G4) -> Aston Villa | J4: =IF(I4<>"",ROWS($I$2:I4),"") -> 3 | K4: =IFERROR(SMALL($J$2:$J$37,ROWS($J$2:J4)),"") -> 3 | L4: {=IFERROR(INDEX($G$2:$G$37,K4),0)} -> Aston Villa | N4: Aston Villa | P4: Aston Villa | R4: =+IFERROR(IFERROR(INDEX(Idiomas!$D$313:$D$348,MATCH(Predictor!C4,Idiomas!$G$313:$G$348,0)),INDEX(Idiomas!$D$313:$D$348,MATCH(Predictor!C4,Idiomas!$H$313:$H$348,0))),"")
B5: =Idiomas!D358 -> Semifinales | E5: =Idiomas!D367 -> ·Una vez selecciones un equipo, dejará de aparecer en el selector | G5: =TablaEquipos[[#This Row],[Team]] -> Atlético Madrid | H5: =C5 -> 0 | I5: =IF(COUNTIF($H$2:$H$37,G5)>=COUNTIF($G$2:$G$37,G5),"",G5) -> Atlético Madrid | J5: =IF(I5<>"",ROWS($I$2:I5),"") -> 4 | K5: =IFERROR(SMALL($J$2:$J$37,ROWS($J$2:J5)),"") -> 4 | L5: {=IFERROR(INDEX($G$2:$G$37,K5),0)} -> Atlético Madrid | N5: Atlético Madrid | P5: Atlético Madrid | R5: =+IFERROR(IFERROR(INDEX(Idiomas!$D$313:$D$348,MATCH(Predictor!C5,Idiomas!$G$313:$G$348,0)),INDEX(Idiomas!$D$313:$D$348,MATCH(Predictor!C5,Idiomas!$H$313:$H$348,0))),"")
B6: =+Idiomas!D359 -> Cuartos de final | G6: =TablaEquipos[[#This Row],[Team]] -> Barcelona | H6: =C6 -> 0 | I6: =IF(COUNTIF($H$2:$H$37,G6)>=COUNTIF($G$2:$G$37,G6),"",G6) -> Barcelona | J6: =IF(I6<>"",ROWS($I$2:I6),"") -> 5 | K6: =IFERROR(SMALL($J$2:$J$37,ROWS($J$2:J6)),"") -> 5 | L6: {=IFERROR(INDEX($G$2:$G$37,K6),0)} -> Barcelona | N6: Barcelona | P6: Barcelona | R6: =+IFERROR(IFERROR(INDEX(Idiomas!$D$313:$D$348,MATCH(Predictor!C6,Idiomas!$G$313:$G$348,0)),INDEX(Idiomas!$D$313:$D$348,MATCH(Predictor!C6,Idiomas!$H$313:$H$348,0))),"")
B7: =+Idiomas!D359 -> Cuartos de final | E7: =Idiomas!D368 -> ·Si has rellenado todos y quieres hacer un cambio, | G7: =TablaEquipos[[#This Row],[Team]] -> Bayern München | H7: =C7 -> 0 | I7: =IF(COUNTIF($H$2:$H$37,G7)>=COUNTIF($G$2:$G$37,G7),"",G7) -> Bayern München | J7: =IF(I7<>"",ROWS($I$2:I7),"") -> 6 | K7: =IFERROR(SMALL($J$2:$J$37,ROWS($J$2:J7)),"") -> 6 | L7: {=IFERROR(INDEX($G$2:$G$37,K7),0)} -> Bayern München | N7: Bayern München | P7: Bayern München | R7: =+IFERROR(IFERROR(INDEX(Idiomas!$D$313:$D$348,MATCH(Predictor!C7,Idiomas!$G$313:$G$348,0)),INDEX(Idiomas!$D$313:$D$348,MATCH(Predictor!C7,Idiomas!$H$313:$H$348,0))),"")
B8: =+Idiomas!D359 -> Cuartos de final | E8: =Idiomas!D369 -> borra los equipos que quieras cambiar y podrás volver a seleccionarlos | G8: =TablaEquipos[[#This Row],[Team]] -> Betis | H8: =C8 -> 0 | I8: =IF(COUNTIF($H$2:$H$37,G8)>=COUNTIF($G$2:$G$37,G8),"",G8) -> Betis | J8: =IF(I8<>"",ROWS($I$2:I8),"") -> 7 | K8: =IFERROR(SMALL($J$2:$J$37,ROWS($J$2:J8)),"") -> 7 | L8: {=IFERROR(INDEX($G$2:$G$37,K8),0)} -> Betis | N8: Betis | P8: Betis | R8: =+IFERROR(IFERROR(INDEX(Idiomas!$D$313:$D$348,MATCH(Predictor!C8,Idiomas!$G$313:$G$348,0)),INDEX(Idiomas!$D$313:$D$348,MATCH(Predictor!C8,Idiomas!$H$313:$H$348,0))),"")
B9: =+Idiomas!D359 -> Cuartos de final | G9: =TablaEquipos[[#This Row],[Team]] -> Bodø/Glimt | H9: =C9 -> 0 | I9: =IF(COUNTIF($H$2:$H$37,G9)>=COUNTIF($G$2:$G$37,G9),"",G9) -> Bodø/Glimt | J9: =IF(I9<>"",ROWS($I$2:I9),"") -> 8 | K9: =IFERROR(SMALL($J$2:$J$37,ROWS($J$2:J9)),"") -> 8 | L9: {=IFERROR(INDEX($G$2:$G$37,K9),0)} -> Bodø/Glimt | N9: Bodø/Glimt | P9: Bodø/Glimt | R9: =+IFERROR(IFERROR(INDEX(Idiomas!$D$313:$D$348,MATCH(Predictor!C9,Idiomas!$G$313:$G$348,0)),INDEX(Idiomas!$D$313:$D$348,MATCH(Predictor!C9,Idiomas!$H$313:$H$348,0))),"")
B10: =+Idiomas!D360 -> Octavos de final | G10: =TablaEquipos[[#This Row],[Team]] -> Borussia Dortmund | H10: =C10 -> 0 | I10: =IF(COUNTIF($H$2:$H$37,G10)>=COUNTIF($G$2:$G$37,G10),"",G10) -> Borussia Dortmund | J10: =IF(I10<>"",ROWS($I$2:I10),"") -> 9 | K10: =IFERROR(SMALL($J$2:$J$37,ROWS($J$2:J10)),"") -> 9 | L10: {=IFERROR(INDEX($G$2:$G$37,K10),0)} -> Borussia Dortmund | N10: Borussia Dortmund | P10: Borussia Dortmund | R10: =+IFERROR(IFERROR(INDEX(Idiomas!$D$313:$D$348,MATCH(Predictor!C10,Idiomas!$G$313:$G$348,0)),INDEX(Idiomas!$D$313:$D$348,MATCH(Predictor!C10,Idiomas!$H$313:$H$348,0))),"")
B11: =+Idiomas!D360 -> Octavos de final | E11: =HYPERLINK(Idiomas!D11,Idiomas!D7) -> Si quieres organizar una porra con tu grupo puedes descargar el archivo para administrarla desde aquí. | G11: =TablaEquipos[[#This Row],[Team]] -> Brugge | H11: =C11 -> 0 | I11: =IF(COUNTIF($H$2:$H$37,G11)>=COUNTIF($G$2:$G$37,G11),"",G11) -> Brugge | J11: =IF(I11<>"",ROWS($I$2:I11),"") -> 10 | K11: =IFERROR(SMALL($J$2:$J$37,ROWS($J$2:J11)),"") -> 10 | L11: {=IFERROR(INDEX($G$2:$G$37,K11),0)} -> Brugge | N11: Brugge | P11: Brugge | R11: =+IFERROR(IFERROR(INDEX(Idiomas!$D$313:$D$348,MATCH(Predictor!C11,Idiomas!$G$313:$G$348,0)),INDEX(Idiomas!$D$313:$D$348,MATCH(Predictor!C11,Idiomas!$H$313:$H$348,0))),"")
B12: =+Idiomas!D360 -> Octavos de final | G12: =TablaEquipos[[#This Row],[Team]] -> Como | H12: =C12 -> 0 | I12: =IF(COUNTIF($H$2:$H$37,G12)>=COUNTIF($G$2:$G$37,G12),"",G12) -> Como | J12: =IF(I12<>"",ROWS($I$2:I12),"") -> 11 | K12: =IFERROR(SMALL($J$2:$J$37,ROWS($J$2:J12)),"") -> 11 | L12: {=IFERROR(INDEX($G$2:$G$37,K12),0)} -> Como | N12: Como | P12: Como | R12: =+IFERROR(IFERROR(INDEX(Idiomas!$D$313:$D$348,MATCH(Predictor!C12,Idiomas!$G$313:$G$348,0)),INDEX(Idiomas!$D$313:$D$348,MATCH(Predictor!C12,Idiomas!$H$313:$H$348,0))),"")
B13: =+Idiomas!D360 -> Octavos de final | G13: =TablaEquipos[[#This Row],[Team]] -> Fenerbahçe | H13: =C13 -> 0 | I13: =IF(COUNTIF($H$2:$H$37,G13)>=COUNTIF($G$2:$G$37,G13),"",G13) -> Fenerbahçe | J13: =IF(I13<>"",ROWS($I$2:I13),"") -> 12 | K13: =IFERROR(SMALL($J$2:$J$37,ROWS($J$2:J13)),"") -> 12 | L13: {=IFERROR(INDEX($G$2:$G$37,K13),0)} -> Fenerbahçe | N13: Fenerbahçe | P13: Fenerbahçe | R13: =+IFERROR(IFERROR(INDEX(Idiomas!$D$313:$D$348,MATCH(Predictor!C13,Idiomas!$G$313:$G$348,0)),INDEX(Idiomas!$D$313:$D$348,MATCH(Predictor!C13,Idiomas!$H$313:$H$348,0))),"")
B14: =+Idiomas!D360 -> Octavos de final | G14: =TablaEquipos[[#This Row],[Team]] -> Feyenoord | H14: =C14 -> 0 | I14: =IF(COUNTIF($H$2:$H$37,G14)>=COUNTIF($G$2:$G$37,G14),"",G14) -> Feyenoord | J14: =IF(I14<>"",ROWS($I$2:I14),"") -> 13 | K14: =IFERROR(SMALL($J$2:$J$37,ROWS($J$2:J14)),"") -> 13 | L14: {=IFERROR(INDEX($G$2:$G$37,K14),0)} -> Feyenoord | N14: Feyenoord | P14: Feyenoord | R14: =+IFERROR(IFERROR(INDEX(Idiomas!$D$313:$D$348,MATCH(Predictor!C14,Idiomas!$G$313:$G$348,0)),INDEX(Idiomas!$D$313:$D$348,MATCH(Predictor!C14,Idiomas!$H$313:$H$348,0))),"")
B15: =+Idiomas!D360 -> Octavos de final | G15: =TablaEquipos[[#This Row],[Team]] -> Galatasaray | H15: =C15 -> 0 | I15: =IF(COUNTIF($H$2:$H$37,G15)>=COUNTIF($G$2:$G$37,G15),"",G15) -> Galatasaray | J15: =IF(I15<>"",ROWS($I$2:I15),"") -> 14 | K15: =IFERROR(SMALL($J$2:$J$37,ROWS($J$2:J15)),"") -> 14 | L15: {=IFERROR(INDEX($G$2:$G$37,K15),0)} -> Galatasaray | N15: Galatasaray | P15: Galatasaray | R15: =+IFERROR(IFERROR(INDEX(Idiomas!$D$313:$D$348,MATCH(Predictor!C15,Idiomas!$G$313:$G$348,0)),INDEX(Idiomas!$D$313:$D$348,MATCH(Predictor!C15,Idiomas!$H$313:$H$348,0))),"")
B16: =+Idiomas!D360 -> Octavos de final | G16: =TablaEquipos[[#This Row],[Team]] -> Inter Milan | H16: =C16 -> 0 | I16: =IF(COUNTIF($H$2:$H$37,G16)>=COUNTIF($G$2:$G$37,G16),"",G16) -> Inter Milan | J16: =IF(I16<>"",ROWS($I$2:I16),"") -> 15 | K16: =IFERROR(SMALL($J$2:$J$37,ROWS($J$2:J16)),"") -> 15 | L16: {=IFERROR(INDEX($G$2:$G$37,K16),0)} -> Inter Milan | N16: Inter Milan | P16: Inter Milan | R16: =+IFERROR(IFERROR(INDEX(Idiomas!$D$313:$D$348,MATCH(Predictor!C16,Idiomas!$G$313:$G$348,0)),INDEX(Idiomas!$D$313:$D$348,MATCH(Predictor!C16,Idiomas!$H$313:$H$348,0))),"")
B17: =+Idiomas!D360 -> Octavos de final | G17: =TablaEquipos[[#This Row],[Team]] -> LASK | H17: =C17 -> 0 | I17: =IF(COUNTIF($H$2:$H$37,G17)>=COUNTIF($G$2:$G$37,G17),"",G17) -> LASK | J17: =IF(I17<>"",ROWS($I$2:I17),"") -> 16 | K17: =IFERROR(SMALL($J$2:$J$37,ROWS($J$2:J17)),"") -> 16 | L17: {=IFERROR(INDEX($G$2:$G$37,K17),0)} -> LASK | N17: LASK | P17: LASK | R17: =+IFERROR(IFERROR(INDEX(Idiomas!$D$313:$D$348,MATCH(Predictor!C17,Idiomas!$G$313:$G$348,0)),INDEX(Idiomas!$D$313:$D$348,MATCH(Predictor!C17,Idiomas!$H$313:$H$348,0))),"")
B18: =+Idiomas!D361 -> Playoffs | G18: =TablaEquipos[[#This Row],[Team]] -> Leipzig | H18: =C18 -> 0 | I18: =IF(COUNTIF($H$2:$H$37,G18)>=COUNTIF($G$2:$G$37,G18),"",G18) -> Leipzig | J18: =IF(I18<>"",ROWS($I$2:I18),"") -> 17 | K18: =IFERROR(SMALL($J$2:$J$37,ROWS($J$2:J18)),"") -> 17 | L18: {=IFERROR(INDEX($G$2:$G$37,K18),0)} -> Leipzig | N18: Leipzig | P18: Leipzig | R18: =+IFERROR(IFERROR(INDEX(Idiomas!$D$313:$D$348,MATCH(Predictor!C18,Idiomas!$G$313:$G$348,0)),INDEX(Idiomas!$D$313:$D$348,MATCH(Predictor!C18,Idiomas!$H$313:$H$348,0))),"")
B19: =+Idiomas!D361 -> Playoffs | G19: =TablaEquipos[[#This Row],[Team]] -> Lens | H19: =C19 -> 0 | I19: =IF(COUNTIF($H$2:$H$37,G19)>=COUNTIF($G$2:$G$37,G19),"",G19) -> Lens | J19: =IF(I19<>"",ROWS($I$2:I19),"") -> 18 | K19: =IFERROR(SMALL($J$2:$J$37,ROWS($J$2:J19)),"") -> 18 | L19: {=IFERROR(INDEX($G$2:$G$37,K19),0)} -> Lens | N19: Lens | P19: Lens | R19: =+IFERROR(IFERROR(INDEX(Idiomas!$D$313:$D$348,MATCH(Predictor!C19,Idiomas!$G$313:$G$348,0)),INDEX(Idiomas!$D$313:$D$348,MATCH(Predictor!C19,Idiomas!$H$313:$H$348,0))),"")
B20: =+Idiomas!D361 -> Playoffs | G20: =TablaEquipos[[#This Row],[Team]] -> Lille | H20: =C20 -> 0 | I20: =IF(COUNTIF($H$2:$H$37,G20)>=COUNTIF($G$2:$G$37,G20),"",G20) -> Lille | J20: =IF(I20<>"",ROWS($I$2:I20),"") -> 19 | K20: =IFERROR(SMALL($J$2:$J$37,ROWS($J$2:J20)),"") -> 19 | L20: {=IFERROR(INDEX($G$2:$G$37,K20),0)} -> Lille | N20: Lille | P20: Lille | R20: =+IFERROR(IFERROR(INDEX(Idiomas!$D$313:$D$348,MATCH(Predictor!C20,Idiomas!$G$313:$G$348,0)),INDEX(Idiomas!$D$313:$D$348,MATCH(Predictor!C20,Idiomas!$H$313:$H$348,0))),"")
B21: =+Idiomas!D361 -> Playoffs | G21: =TablaEquipos[[#This Row],[Team]] -> Liverpool | H21: =C21 -> 0 | I21: =IF(COUNTIF($H$2:$H$37,G21)>=COUNTIF($G$2:$G$37,G21),"",G21) -> Liverpool | J21: =IF(I21<>"",ROWS($I$2:I21),"") -> 20 | K21: =IFERROR(SMALL($J$2:$J$37,ROWS($J$2:J21)),"") -> 20 | L21: {=IFERROR(INDEX($G$2:$G$37,K21),0)} -> Liverpool | N21: Liverpool | P21: Liverpool | R21: =+IFERROR(IFERROR(INDEX(Idiomas!$D$313:$D$348,MATCH(Predictor!C21,Idiomas!$G$313:$G$348,0)),INDEX(Idiomas!$D$313:$D$348,MATCH(Predictor!C21,Idiomas!$H$313:$H$348,0))),"")
B22: =+Idiomas!D361 -> Playoffs | G22: =TablaEquipos[[#This Row],[Team]] -> Manchester City | H22: =C22 -> 0 | I22: =IF(COUNTIF($H$2:$H$37,G22)>=COUNTIF($G$2:$G$37,G22),"",G22) -> Manchester City | J22: =IF(I22<>"",ROWS($I$2:I22),"") -> 21 | K22: =IFERROR(SMALL($J$2:$J$37,ROWS($J$2:J22)),"") -> 21 | L22: {=IFERROR(INDEX($G$2:$G$37,K22),0)} -> Manchester City | N22: Manchester City | P22: Manchester City | R22: =+IFERROR(IFERROR(INDEX(Idiomas!$D$313:$D$348,MATCH(Predictor!C22,Idiomas!$G$313:$G$348,0)),INDEX(Idiomas!$D$313:$D$348,MATCH(Predictor!C22,Idiomas!$H$313:$H$348,0))),"")
B23: =+Idiomas!D361 -> Playoffs | G23: =TablaEquipos[[#This Row],[Team]] -> Manchester United | H23: =C23 -> 0 | I23: =IF(COUNTIF($H$2:$H$37,G23)>=COUNTIF($G$2:$G$37,G23),"",G23) -> Manchester United | J23: =IF(I23<>"",ROWS($I$2:I23),"") -> 22 | K23: =IFERROR(SMALL($J$2:$J$37,ROWS($J$2:J23)),"") -> 22 | L23: {=IFERROR(INDEX($G$2:$G$37,K23),0)} -> Manchester United | N23: Manchester United | P23: Manchester United | R23: =+IFERROR(IFERROR(INDEX(Idiomas!$D$313:$D$348,MATCH(Predictor!C23,Idiomas!$G$313:$G$348,0)),INDEX(Idiomas!$D$313:$D$348,MATCH(Predictor!C23,Idiomas!$H$313:$H$348,0))),"")
B24: =+Idiomas!D361 -> Playoffs | G24: =TablaEquipos[[#This Row],[Team]] -> Napoli | H24: =C24 -> 0 | I24: =IF(COUNTIF($H$2:$H$37,G24)>=COUNTIF($G$2:$G$37,G24),"",G24) -> Napoli | J24: =IF(I24<>"",ROWS($I$2:I24),"") -> 23 | K24: =IFERROR(SMALL($J$2:$J$37,ROWS($J$2:J24)),"") -> 23 | L24: {=IFERROR(INDEX($G$2:$G$37,K24),0)} -> Napoli | N24: Napoli | P24: Napoli | R24: =+IFERROR(IFERROR(INDEX(Idiomas!$D$313:$D$348,MATCH(Predictor!C24,Idiomas!$G$313:$G$348,0)),INDEX(Idiomas!$D$313:$D$348,MATCH(Predictor!C24,Idiomas!$H$313:$H$348,0))),"")
B25: =+Idiomas!D361 -> Playoffs | G25: =TablaEquipos[[#This Row],[Team]] -> Porto | H25: =C25 -> 0 | I25: =IF(COUNTIF($H$2:$H$37,G25)>=COUNTIF($G$2:$G$37,G25),"",G25) -> Porto | J25: =IF(I25<>"",ROWS($I$2:I25),"") -> 24 | K25: =IFERROR(SMALL($J$2:$J$37,ROWS($J$2:J25)),"") -> 24 | L25: {=IFERROR(INDEX($G$2:$G$37,K25),0)} -> Porto | N25: Porto | P25: Porto | R25: =+IFERROR(IFERROR(INDEX(Idiomas!$D$313:$D$348,MATCH(Predictor!C25,Idiomas!$G$313:$G$348,0)),INDEX(Idiomas!$D$313:$D$348,MATCH(Predictor!C25,Idiomas!$H$313:$H$348,0))),"")
B26: =+Idiomas!D362 -> Fase de Liga | G26: =TablaEquipos[[#This Row],[Team]] -> PSG | H26: =C26 -> 0 | I26: =IF(COUNTIF($H$2:$H$37,G26)>=COUNTIF($G$2:$G$37,G26),"",G26) -> PSG | J26: =IF(I26<>"",ROWS($I$2:I26),"") -> 25 | K26: =IFERROR(SMALL($J$2:$J$37,ROWS($J$2:J26)),"") -> 25 | L26: {=IFERROR(INDEX($G$2:$G$37,K26),0)} -> PSG | N26: PSG | P26: PSG | R26: =+IFERROR(IFERROR(INDEX(Idiomas!$D$313:$D$348,MATCH(Predictor!C26,Idiomas!$G$313:$G$348,0)),INDEX(Idiomas!$D$313:$D$348,MATCH(Predictor!C26,Idiomas!$H$313:$H$348,0))),"")
B27: =+Idiomas!D362 -> Fase de Liga | G27: =TablaEquipos[[#This Row],[Team]] -> PSV Eindhoven | H27: =C27 -> 0 | I27: =IF(COUNTIF($H$2:$H$37,G27)>=COUNTIF($G$2:$G$37,G27),"",G27) -> PSV Eindhoven | J27: =IF(I27<>"",ROWS($I$2:I27),"") -> 26 | K27: =IFERROR(SMALL($J$2:$J$37,ROWS($J$2:J27)),"") -> 26 | L27: {=IFERROR(INDEX($G$2:$G$37,K27),0)} -> PSV Eindhoven | N27: PSV Eindhoven | P27: PSV Eindhoven | R27: =+IFERROR(IFERROR(INDEX(Idiomas!$D$313:$D$348,MATCH(Predictor!C27,Idiomas!$G$313:$G$348,0)),INDEX(Idiomas!$D$313:$D$348,MATCH(Predictor!C27,Idiomas!$H$313:$H$348,0))),"")
B28: =+Idiomas!D362 -> Fase de Liga | G28: =TablaEquipos[[#This Row],[Team]] -> Real Madrid | H28: =C28 -> 0 | I28: =IF(COUNTIF($H$2:$H$37,G28)>=COUNTIF($G$2:$G$37,G28),"",G28) -> Real Madrid | J28: =IF(I28<>"",ROWS($I$2:I28),"") -> 27 | K28: =IFERROR(SMALL($J$2:$J$37,ROWS($J$2:J28)),"") -> 27 | L28: {=IFERROR(INDEX($G$2:$G$37,K28),0)} -> Real Madrid | N28: Real Madrid | P28: Real Madrid | R28: =+IFERROR(IFERROR(INDEX(Idiomas!$D$313:$D$348,MATCH(Predictor!C28,Idiomas!$G$313:$G$348,0)),INDEX(Idiomas!$D$313:$D$348,MATCH(Predictor!C28,Idiomas!$H$313:$H$348,0))),"")
B29: =+Idiomas!D362 -> Fase de Liga | G29: =TablaEquipos[[#This Row],[Team]] -> Roma | H29: =C29 -> 0 | I29: =IF(COUNTIF($H$2:$H$37,G29)>=COUNTIF($G$2:$G$37,G29),"",G29) -> Roma | J29: =IF(I29<>"",ROWS($I$2:I29),"") -> 28 | K29: =IFERROR(SMALL($J$2:$J$37,ROWS($J$2:J29)),"") -> 28 | L29: {=IFERROR(INDEX($G$2:$G$37,K29),0)} -> Roma | N29: Roma | P29: Roma | R29: =+IFERROR(IFERROR(INDEX(Idiomas!$D$313:$D$348,MATCH(Predictor!C29,Idiomas!$G$313:$G$348,0)),INDEX(Idiomas!$D$313:$D$348,MATCH(Predictor!C29,Idiomas!$H$313:$H$348,0))),"")
B30: =+Idiomas!D362 -> Fase de Liga | G30: =TablaEquipos[[#This Row],[Team]] -> Sabah | H30: =C30 -> 0 | I30: =IF(COUNTIF($H$2:$H$37,G30)>=COUNTIF($G$2:$G$37,G30),"",G30) -> Sabah | J30: =IF(I30<>"",ROWS($I$2:I30),"") -> 29 | K30: =IFERROR(SMALL($J$2:$J$37,ROWS($J$2:J30)),"") -> 29 | L30: {=IFERROR(INDEX($G$2:$G$37,K30),0)} -> Sabah | N30: Sabah | P30: Sabah | R30: =+IFERROR(IFERROR(INDEX(Idiomas!$D$313:$D$348,MATCH(Predictor!C30,Idiomas!$G$313:$G$348,0)),INDEX(Idiomas!$D$313:$D$348,MATCH(Predictor!C30,Idiomas!$H$313:$H$348,0))),"")
B31: =+Idiomas!D362 -> Fase de Liga | G31: =TablaEquipos[[#This Row],[Team]] -> Shakhtar Donetsk | H31: =C31 -> 0 | I31: =IF(COUNTIF($H$2:$H$37,G31)>=COUNTIF($G$2:$G$37,G31),"",G31) -> Shakhtar Donetsk | J31: =IF(I31<>"",ROWS($I$2:I31),"") -> 30 | K31: =IFERROR(SMALL($J$2:$J$37,ROWS($J$2:J31)),"") -> 30 | L31: {=IFERROR(INDEX($G$2:$G$37,K31),0)} -> Shakhtar Donetsk | N31: Shakhtar Donetsk | P31: Shakhtar Donetsk | R31: =+IFERROR(IFERROR(INDEX(Idiomas!$D$313:$D$348,MATCH(Predictor!C31,Idiomas!$G$313:$G$348,0)),INDEX(Idiomas!$D$313:$D$348,MATCH(Predictor!C31,Idiomas!$H$313:$H$348,0))),"")
B32: =+Idiomas!D362 -> Fase de Liga | G32: =TablaEquipos[[#This Row],[Team]] -> Slavia Praha | H32: =C32 -> 0 | I32: =IF(COUNTIF($H$2:$H$37,G32)>=COUNTIF($G$2:$G$37,G32),"",G32) -> Slavia Praha | J32: =IF(I32<>"",ROWS($I$2:I32),"") -> 31 | K32: =IFERROR(SMALL($J$2:$J$37,ROWS($J$2:J32)),"") -> 31 | L32: {=IFERROR(INDEX($G$2:$G$37,K32),0)} -> Slavia Praha | N32: Slavia Praha | P32: Slavia Praha | R32: =+IFERROR(IFERROR(INDEX(Idiomas!$D$313:$D$348,MATCH(Predictor!C32,Idiomas!$G$313:$G$348,0)),INDEX(Idiomas!$D$313:$D$348,MATCH(Predictor!C32,Idiomas!$H$313:$H$348,0))),"")
B33: =+Idiomas!D362 -> Fase de Liga | G33: =TablaEquipos[[#This Row],[Team]] -> Slovan Bratislava | H33: =C33 -> 0 | I33: =IF(COUNTIF($H$2:$H$37,G33)>=COUNTIF($G$2:$G$37,G33),"",G33) -> Slovan Bratislava | J33: =IF(I33<>"",ROWS($I$2:I33),"") -> 32 | K33: =IFERROR(SMALL($J$2:$J$37,ROWS($J$2:J33)),"") -> 32 | L33: {=IFERROR(INDEX($G$2:$G$37,K33),0)} -> Slovan Bratislava | N33: Slovan Bratislava | P33: Slovan Bratislava | R33: =+IFERROR(IFERROR(INDEX(Idiomas!$D$313:$D$348,MATCH(Predictor!C33,Idiomas!$G$313:$G$348,0)),INDEX(Idiomas!$D$313:$D$348,MATCH(Predictor!C33,Idiomas!$H$313:$H$348,0))),"")
B34: =+Idiomas!D362 -> Fase de Liga | G34: =TablaEquipos[[#This Row],[Team]] -> Sporting Portugal | H34: =C34 -> 0 | I34: =IF(COUNTIF($H$2:$H$37,G34)>=COUNTIF($G$2:$G$37,G34),"",G34) -> Sporting Portugal | J34: =IF(I34<>"",ROWS($I$2:I34),"") -> 33 | K34: =IFERROR(SMALL($J$2:$J$37,ROWS($J$2:J34)),"") -> 33 | L34: {=IFERROR(INDEX($G$2:$G$37,K34),0)} -> Sporting Portugal | N34: Sporting Portugal | P34: Sporting Portugal | R34: =+IFERROR(IFERROR(INDEX(Idiomas!$D$313:$D$348,MATCH(Predictor!C34,Idiomas!$G$313:$G$348,0)),INDEX(Idiomas!$D$313:$D$348,MATCH(Predictor!C34,Idiomas!$H$313:$H$348,0))),"")
B35: =+Idiomas!D362 -> Fase de Liga | G35: =TablaEquipos[[#This Row],[Team]] -> Stuttgart | H35: =C35 -> 0 | I35: =IF(COUNTIF($H$2:$H$37,G35)>=COUNTIF($G$2:$G$37,G35),"",G35) -> Stuttgart | J35: =IF(I35<>"",ROWS($I$2:I35),"") -> 34 | K35: =IFERROR(SMALL($J$2:$J$37,ROWS($J$2:J35)),"") -> 34 | L35: {=IFERROR(INDEX($G$2:$G$37,K35),0)} -> Stuttgart | N35: Stuttgart | P35: Stuttgart | R35: =+IFERROR(IFERROR(INDEX(Idiomas!$D$313:$D$348,MATCH(Predictor!C35,Idiomas!$G$313:$G$348,0)),INDEX(Idiomas!$D$313:$D$348,MATCH(Predictor!C35,Idiomas!$H$313:$H$348,0))),"")
B36: =+Idiomas!D362 -> Fase de Liga | G36: =TablaEquipos[[#This Row],[Team]] -> Viking | H36: =C36 -> 0 | I36: =IF(COUNTIF($H$2:$H$37,G36)>=COUNTIF($G$2:$G$37,G36),"",G36) -> Viking | J36: =IF(I36<>"",ROWS($I$2:I36),"") -> 35 | K36: =IFERROR(SMALL($J$2:$J$37,ROWS($J$2:J36)),"") -> 35 | L36: {=IFERROR(INDEX($G$2:$G$37,K36),0)} -> Viking | N36: Viking | P36: Viking | R36: =+IFERROR(IFERROR(INDEX(Idiomas!$D$313:$D$348,MATCH(Predictor!C36,Idiomas!$G$313:$G$348,0)),INDEX(Idiomas!$D$313:$D$348,MATCH(Predictor!C36,Idiomas!$H$313:$H$348,0))),"")
B37: =+Idiomas!D362 -> Fase de Liga | G37: =TablaEquipos[[#This Row],[Team]] -> Villarreal | H37: =C37 -> 0 | I37: =IF(COUNTIF($H$2:$H$37,G37)>=COUNTIF($G$2:$G$37,G37),"",G37) -> Villarreal | J37: =IF(I37<>"",ROWS($I$2:I37),"") -> 36 | K37: =IFERROR(SMALL($J$2:$J$37,ROWS($J$2:J37)),"") -> 36 | L37: {=IFERROR(INDEX($G$2:$G$37,K37),0)} -> Villarreal | N37: Villarreal | P37: Villarreal | R37: =+IFERROR(IFERROR(INDEX(Idiomas!$D$313:$D$348,MATCH(Predictor!C37,Idiomas!$G$313:$G$348,0)),INDEX(Idiomas!$D$313:$D$348,MATCH(Predictor!C37,Idiomas!$H$313:$H$348,0))),"")

Sheet League
A1: =Idiomas!D22 -> Jor. | B1: =Idiomas!D20 -> Fecha | C1: =Idiomas!D21 -> Hora | D1: =Idiomas!D23 -> Equipo Local | E1: Badge | F1: P | G1: =Idiomas!D24 -> Gol | H1: =Idiomas!D25 -> Gol | I1: P | J1: Badge | K1: =Idiomas!D26 -> Equipo Visitante | N1: =Idiomas!D52 -> Pos | O1: Badge | P1: =Idiomas!$D53 -> Equipo | Q1: =Idiomas!$D54 -> Pts | R1: =Idiomas!$D55 -> J | S1: =Idiomas!$D56 -> G | T1: =Idiomas!$D57 -> E | U1: =Idiomas!$D58 -> P | V1: =Idiomas!$D59 -> GF | W1: =Idiomas!$D60 -> GC | X1: =Idiomas!$D61 -> DG | Y1: =CONCATENATE(Q1&" "&Idiomas!$D62) -> Pts C | Z1: =CONCATENATE(R1&" "&Idiomas!$D62) -> J C | AA1: =CONCATENATE(S1&" "&Idiomas!$D62) -> G C | AB1: =CONCATENATE(T1&" "&Idiomas!$D62) -> E C | AC1: =CONCATENATE(U1&" "&Idiomas!$D62) -> P C | AD1: =CONCATENATE(V1&" "&Idiomas!$D62) -> GF C | AE1: =CONCATENATE(W1&" "&Idiomas!$D62) -> GC C | AF1: =CONCATENATE(X1&" "&Idiomas!$D62) -> DG C | AG1: =CONCATENATE(Q1&" "&Idiomas!$D63) -> Pts F | AH1: =CONCATENATE(R1&" "&Idiomas!$D63) -> J F | AI1: =CONCATENATE(S1&" "&Idiomas!$D63) -> G F | AJ1: =CONCATENATE(T1&" "&Idiomas!$D63) -> E F | AK1: =CONCATENATE(U1&" "&Idiomas!$D63) -> P F | AL1: =CONCATENATE(V1&" "&Idiomas!$D63) -> GF F | AM1: =CONCATENATE(W1&" "&Idiomas!$D63) -> GC F | AN1: =CONCATENATE(X1&" "&Idiomas!$D63) -> DG F | AO1: P-O | AP1: DF-O | AQ1: GF_O | AS1: =Idiomas!D65 -> Seleccionar el orden de los empatados. | AV1: =COUNTIF($AV$2:$AV$37,">"&1) -> 36 | AZ1: =P1 -> Equipo | BA1: =Idiomas!D64 -> Puntos penalizados | BF1: Winner | BI1: {=TRANSPOSE(Calcs!$A$2:$A$37)} -> AEK | BJ1: Arsenal | BK1: Aston Villa | BL1: Atlético Madrid | BM1: Barcelona | BN1: Bayern München | BO1: Betis | BP1: Bodø/Glimt | BQ1: Borussia Dortmund | BR1: Brugge | BS1: Como | BT1: Fenerbahçe | BU1: Feyenoord | BV1: Galatasaray | BW1: Inter Milan | BX1: LASK | BY1: Leipzig | BZ1: Lens | CA1: Lille | CB1: Liverpool | CC1: Manchester City | CD1: Manchester United | CE1: Napoli | CF1: Porto | CG1: PSG | CH1: PSV Eindhoven | CI1: Real Madrid | CJ1: Roma | CK1: Sabah | CL1: Shakhtar Donetsk | CM1: Slavia Praha | CN1: Slovan Bratislava | CO1: Sporting Portugal | CP1: Stuttgart | CQ1: Viking | CR1: Villarreal
A2: 1 | B2: =Horarios!C2 -> 46273.781 | C2: =Horarios!C2 -> 46273.781 | D2: AEK | E2: {=badge_home} -> #VALUE! | J2: {=badge_away} -> #VALUE! | K2: LASK | L2: =IFERROR(IF(TYPE(Teams!$B$2)=128,INDEX(TablaEquipos[Badge],MATCH(League!C3,TablaEquipos[Team],0)),""),"") | N2: 1 | O2: {=badge_away} -> #VALUE! | P2: =IFERROR(INDEX(Calcs!A$2:A$37,MATCH($N2,Calcs!$CJ$2:$CJ$37,0)),"") -> AEK | Q2: =IFERROR(INDEX(Calcs!$B$2:$AB$37,MATCH($N2,Calcs!$CJ$2:$CJ$37,0),MATCH(Q$1,Calcs!$B$1:$AB$1,0)),"") -> 0 | R2: =IFERROR(INDEX(Calcs!$B$2:$AB$37,MATCH($N2,Calcs!$CJ$2:$CJ$37,0),MATCH(R$1,Calcs!$B$1:$AB$1,0)),"") -> 0 | S2: =IFERROR(INDEX(Calcs!$B$2:$AB$37,MATCH($N2,Calcs!$CJ$2:$CJ$37,0),MATCH(S$1,Calcs!$B$1:$AB$1,0)),"") -> 0 | T2: =IFERROR(INDEX(Calcs!$B$2:$AB$37,MATCH($N2,Calcs!$CJ$2:$CJ$37,0),MATCH(T$1,Calcs!$B$1:$AB$1,0)),"") -> 0 | U2: =IFERROR(INDEX(Calcs!$B$2:$AB$37,MATCH($N2,Calcs!$CJ$2:$CJ$37,0),MATCH(U$1,Calcs!$B$1:$AB$1,0)),"") -> 0 | V2: =IFERROR(INDEX(Calcs!$B$2:$AB$37,MATCH($N2,Calcs!$CJ$2:$CJ$37,0),MATCH(V$1,Calcs!$B$1:$AB$1,0)),"") -> 0 | W2: =IFERROR(INDEX(Calcs!$B$2:$AB$37,MATCH($N2,Calcs!$CJ$2:$CJ$37,0),MATCH(W$1,Calcs!$B$1:$AB$1,0)),"") -> 0 | X2: =IFERROR(INDEX(Calcs!$B$2:$AB$37,MATCH($N2,Calcs!$CJ$2:$CJ$37,0),MATCH(X$1,Calcs!$B$1:$AB$1,0)),"") -> 0 | ... AQ2: =IFERROR(INDEX(Calcs!$B$2:$AB$37,MATCH($N2,Calcs!$CJ$2:$CJ$37,0),MATCH(AQ$1,Calcs!$B$1:$AB$1,0)),"") -> 0 | AS2: =INDEX(Calcs!A$2:A$37,MATCH($N2,Calcs!$CF$2:$CF$37,0)) -> AEK | AU2: =INDEX(Calcs!$BZ$2:$BZ$37,MATCH($AS2,Calcs!$A$2:$A$37,0)) -> 1 | AV2: =COUNTIF($AU$2:$AU$37,$AU2) -> 36 | AW2: =AU2&"."&AV2 -> 1.36 | AX2: {=OFFSET($N$2,AU2-1,0,AV2,1)} -> 1 | AZ2: =TablaEquipos[[#This Row],[Team]] -> AEK | BF2: =IF(OR(G2="",H2=""),"Pendiente",IF(G2>H2,"Local",IF(G2<H2,"Visitante","Empate"))) -> Pendiente | BG2: {=IFERROR(INDEX(Equipo_local,SMALL(IF(BI$1=Equipo_visitante,ROW(Equipo_local)-MIN(ROW(Equipo_visitante))+1,""),ROW()-1)),"")} -> Shakhtar Donetsk | BH2: 1 | BI2: {=IFERROR(INDEX(Equipo_visitante,MATCH($BH2&BI$1,Jornada&Equipo_local,0)),INDEX(Equipo_local,MATCH($BH2&BI$1,Jornada&Equipo_visitante,0)))} -> LASK | BJ2: {=IFERROR(INDEX(Equipo_visitante,MATCH($BH2&BJ$1,Jornada&Equipo_local,0)),INDEX(Equipo_local,MATCH($BH2&BJ$1,Jornada&Equipo_visitante,0)))} -> Napoli | BK2: {=IFERROR(INDEX(Equipo_visitante,MATCH($BH2&BK$1,Jornada&Equipo_local,0)),INDEX(Equipo_local,MATCH($BH2&BK$1,Jornada&Equipo_visitante,0)))} -> Brugge | BL2: {=IFERROR(INDEX(Equipo_visitante,MATCH($BH2&BL$1,Jornada&Equipo_local,0)),INDEX(Equipo_local,MATCH($BH2&BL$1,Jornada&Equipo_visitante,0)))} -> Liverpool | BM2: {=IFERROR(INDEX(Equipo_visitante,MATCH($BH2&BM$1,Jornada&Equipo_local,0)),INDEX(Equipo_local,MATCH($BH2&BM$1,Jornada&Equipo_visitante,0)))} -> Feyenoord | BN2: {=IFERROR(INDEX(Equipo_visitante,MATCH($BH2&BN$1,Jornada&Equipo_local,0)),INDEX(Equipo_local,MATCH($BH2&BN$1,Jornada&Equipo_visitante,0)))} -> Bodø/Glimt | BO2: {=IFERROR(INDEX(Equipo_visitante,MATCH($BH2&BO$1,Jornada&Equipo_local,0)),INDEX(Equipo_local,MATCH($BH2&BO$1,Jornada&Equipo_visitante,0)))} -> Lille | BP2: {=IFERROR(INDEX(Equipo_visitante,MATCH($BH2&BP$1,Jornada&Equipo_local,0)),INDEX(Equipo_local,MATCH($BH2&BP$1,Jornada&Equipo_visitante,0)))} -> Bayern München | ... CR2: {=IFERROR(INDEX(Equipo_visitante,MATCH($BH2&CR$1,Jornada&Equipo_local,0)),INDEX(Equipo_local,MATCH($BH2&CR$1,Jornada&Equipo_visitante,0)))} -> Borussia Dortmund
A3: 1 | B3: =Horarios!C3 -> 46273.781 | C3: =Horarios!C3 -> 46273.781 | D3: Brugge | E3: {=badge_home} -> #VALUE! | J3: {=badge_away} -> #VALUE! | K3: Aston Villa | N3: 2 | O3: {=badge_away} -> #VALUE! | P3: =IFERROR(INDEX(Calcs!A$2:A$37,MATCH($N3,Calcs!$CJ$2:$CJ$37,0)),"") -> Arsenal | Q3: =IFERROR(INDEX(Calcs!$B$2:$AB$37,MATCH($N3,Calcs!$CJ$2:$CJ$37,0),MATCH(Q$1,Calcs!$B$1:$AB$1,0)),"") -> 0 | R3: =IFERROR(INDEX(Calcs!$B$2:$AB$37,MATCH($N3,Calcs!$CJ$2:$CJ$37,0),MATCH(R$1,Calcs!$B$1:$AB$1,0)),"") -> 0 | S3: =IFERROR(INDEX(Calcs!$B$2:$AB$37,MATCH($N3,Calcs!$CJ$2:$CJ$37,0),MATCH(S$1,Calcs!$B$1:$AB$1,0)),"") -> 0 | T3: =IFERROR(INDEX(Calcs!$B$2:$AB$37,MATCH($N3,Calcs!$CJ$2:$CJ$37,0),MATCH(T$1,Calcs!$B$1:$AB$1,0)),"") -> 0 | U3: =IFERROR(INDEX(Calcs!$B$2:$AB$37,MATCH($N3,Calcs!$CJ$2:$CJ$37,0),MATCH(U$1,Calcs!$B$1:$AB$1,0)),"") -> 0 | V3: =IFERROR(INDEX(Calcs!$B$2:$AB$37,MATCH($N3,Calcs!$CJ$2:$CJ$37,0),MATCH(V$1,Calcs!$B$1:$AB$1,0)),"") -> 0 | W3: =IFERROR(INDEX(Calcs!$B$2:$AB$37,MATCH($N3,Calcs!$CJ$2:$CJ$37,0),MATCH(W$1,Calcs!$B$1:$AB$1,0)),"") -> 0 | X3: =IFERROR(INDEX(Calcs!$B$2:$AB$37,MATCH($N3,Calcs!$CJ$2:$CJ$37,0),MATCH(X$1,Calcs!$B$1:$AB$1,0)),"") -> 0 | ... AQ3: =IFERROR(INDEX(Calcs!$B$2:$AB$37,MATCH($N3,Calcs!$CJ$2:$CJ$37,0),MATCH(AQ$1,Calcs!$B$1:$AB$1,0)),"") -> 0 | AS3: =INDEX(Calcs!A$2:A$37,MATCH($N3,Calcs!$CF$2:$CF$37,0)) -> Arsenal | AU3: =INDEX(Calcs!$BZ$2:$BZ$37,MATCH($AS3,Calcs!$A$2:$A$37,0)) -> 1 | AV3: =COUNTIF($AU$2:$AU$37,$AU3) -> 36 | AW3: =AU3&"."&AV3 -> 1.36 | AX3: 2 | AZ3: =TablaEquipos[[#This Row],[Team]] -> Arsenal | BF3: =IF(OR(G3="",H3=""),"Pendiente",IF(G3>H3,"Local",IF(G3<H3,"Visitante","Empate"))) -> Pendiente | BH3: 2 | BI3: {=IFERROR(INDEX(Equipo_visitante,MATCH($BH3&BI$1,Jornada&Equipo_local,0)),INDEX(Equipo_local,MATCH($BH3&BI$1,Jornada&Equipo_visitante,0)))} -> Shakhtar Donetsk | BJ3: {=IFERROR(INDEX(Equipo_visitante,MATCH($BH3&BJ$1,Jornada&Equipo_local,0)),INDEX(Equipo_local,MATCH($BH3&BJ$1,Jornada&Equipo_visitante,0)))} -> Lille | BK3: {=IFERROR(INDEX(Equipo_visitante,MATCH($BH3&BK$1,Jornada&Equipo_local,0)),INDEX(Equipo_local,MATCH($BH3&BK$1,Jornada&Equipo_visitante,0)))} -> Fenerbahçe | BL3: {=IFERROR(INDEX(Equipo_visitante,MATCH($BH3&BL$1,Jornada&Equipo_local,0)),INDEX(Equipo_local,MATCH($BH3&BL$1,Jornada&Equipo_visitante,0)))} -> Manchester United | BM3: {=IFERROR(INDEX(Equipo_visitante,MATCH($BH3&BM$1,Jornada&Equipo_local,0)),INDEX(Equipo_local,MATCH($BH3&BM$1,Jornada&Equipo_visitante,0)))} -> Galatasaray | BN3: {=IFERROR(INDEX(Equipo_visitante,MATCH($BH3&BN$1,Jornada&Equipo_local,0)),INDEX(Equipo_local,MATCH($BH3&BN$1,Jornada&Equipo_visitante,0)))} -> Viking | BO3: {=IFERROR(INDEX(Equipo_visitante,MATCH($BH3&BO$1,Jornada&Equipo_local,0)),INDEX(Equipo_local,MATCH($BH3&BO$1,Jornada&Equipo_visitante,0)))} -> Porto | BP3: {=IFERROR(INDEX(Equipo_visitante,MATCH($BH3&BP$1,Jornada&Equipo_local,0)),INDEX(Equipo_local,MATCH($BH3&BP$1,Jornada&Equipo_visitante,0)))} -> Borussia Dortmund | ... CR3: {=IFERROR(INDEX(Equipo_visitante,MATCH($BH3&CR$1,Jornada&Equipo_local,0)),INDEX(Equipo_local,MATCH($BH3&CR$1,Jornada&Equipo_visitante,0)))} -> Napoli
A4: 1 | B4: =Horarios!C4 -> 46273.875 | C4: =Horarios!C4 -> 46273.875 | D4: Borussia Dortmund | E4: {=badge_home} -> #VALUE! | J4: {=badge_away} -> #VALUE! | K4: Villarreal | N4: 3 | O4: {=badge_away} -> #VALUE! | P4: =IFERROR(INDEX(Calcs!A$2:A$37,MATCH($N4,Calcs!$CJ$2:$CJ$37,0)),"") -> Aston Villa | Q4: =IFERROR(INDEX(Calcs!$B$2:$AB$37,MATCH($N4,Calcs!$CJ$2:$CJ$37,0),MATCH(Q$1,Calcs!$B$1:$AB$1,0)),"") -> 0 | R4: =IFERROR(INDEX(Calcs!$B$2:$AB$37,MATCH($N4,Calcs!$CJ$2:$CJ$37,0),MATCH(R$1,Calcs!$B$1:$AB$1,0)),"") -> 0 | S4: =IFERROR(INDEX(Calcs!$B$2:$AB$37,MATCH($N4,Calcs!$CJ$2:$CJ$37,0),MATCH(S$1,Calcs!$B$1:$AB$1,0)),"") -> 0 | T4: =IFERROR(INDEX(Calcs!$B$2:$AB$37,MATCH($N4,Calcs!$CJ$2:$CJ$37,0),MATCH(T$1,Calcs!$B$1:$AB$1,0)),"") -> 0 | U4: =IFERROR(INDEX(Calcs!$B$2:$AB$37,MATCH($N4,Calcs!$CJ$2:$CJ$37,0),MATCH(U$1,Calcs!$B$1:$AB$1,0)),"") -> 0 | V4: =IFERROR(INDEX(Calcs!$B$2:$AB$37,MATCH($N4,Calcs!$CJ$2:$CJ$37,0),MATCH(V$1,Calcs!$B$1:$AB$1,0)),"") -> 0 | W4: =IFERROR(INDEX(Calcs!$B$2:$AB$37,MATCH($N4,Calcs!$CJ$2:$CJ$37,0),MATCH(W$1,Calcs!$B$1:$AB$1,0)),"") -> 0 | X4: =IFERROR(INDEX(Calcs!$B$2:$AB$37,MATCH($N4,Calcs!$CJ$2:$CJ$37,0),MATCH(X$1,Calcs!$B$1:$AB$1,0)),"") -> 0 | ... AQ4: =IFERROR(INDEX(Calcs!$B$2:$AB$37,MATCH($N4,Calcs!$CJ$2:$CJ$37,0),MATCH(AQ$1,Calcs!$B$1:$AB$1,0)),"") -> 0 | AS4: =INDEX(Calcs!A$2:A$37,MATCH($N4,Calcs!$CF$2:$CF$37,0)) -> Aston Villa | AU4: =INDEX(Calcs!$BZ$2:$BZ$37,MATCH($AS4,Calcs!$A$2:$A$37,0)) -> 1 | AV4: =COUNTIF($AU$2:$AU$37,$AU4) -> 36 | AW4: =AU4&"."&AV4 -> 1.36 | AX4: 3 | AZ4: =TablaEquipos[[#This Row],[Team]] -> Aston Villa | BF4: =IF(OR(G4="",H4=""),"Pendiente",IF(G4>H4,"Local",IF(G4<H4,"Visitante","Empate"))) -> Pendiente | BH4: 3 | BI4: {=IFERROR(INDEX(Equipo_visitante,MATCH($BH4&BI$1,Jornada&Equipo_local,0)),INDEX(Equipo_local,MATCH($BH4&BI$1,Jornada&Equipo_visitante,0)))} -> Manchester City | BJ4: {=IFERROR(INDEX(Equipo_visitante,MATCH($BH4&BJ$1,Jornada&Equipo_local,0)),INDEX(Equipo_local,MATCH($BH4&BJ$1,Jornada&Equipo_visitante,0)))} -> Bayern München | BK4: {=IFERROR(INDEX(Equipo_visitante,MATCH($BH4&BK$1,Jornada&Equipo_local,0)),INDEX(Equipo_local,MATCH($BH4&BK$1,Jornada&Equipo_visitante,0)))} -> Viking | BL4: {=IFERROR(INDEX(Equipo_visitante,MATCH($BH4&BL$1,Jornada&Equipo_local,0)),INDEX(Equipo_local,MATCH($BH4&BL$1,Jornada&Equipo_visitante,0)))} -> Stuttgart | BM4: {=IFERROR(INDEX(Equipo_visitante,MATCH($BH4&BM$1,Jornada&Equipo_local,0)),INDEX(Equipo_local,MATCH($BH4&BM$1,Jornada&Equipo_visitante,0)))} -> PSG | BN4: {=IFERROR(INDEX(Equipo_visitante,MATCH($BH4&BN$1,Jornada&Equipo_local,0)),INDEX(Equipo_local,MATCH($BH4&BN$1,Jornada&Equipo_visitante,0)))} -> Arsenal | BO4: {=IFERROR(INDEX(Equipo_visitante,MATCH($BH4&BO$1,Jornada&Equipo_local,0)),INDEX(Equipo_local,MATCH($BH4&BO$1,Jornada&Equipo_visitante,0)))} -> Feyenoord | BP4: {=IFERROR(INDEX(Equipo_visitante,MATCH($BH4&BP$1,Jornada&Equipo_local,0)),INDEX(Equipo_local,MATCH($BH4&BP$1,Jornada&Equipo_visitante,0)))} -> Napoli | ... CR4: {=IFERROR(INDEX(Equipo_visitante,MATCH($BH4&CR$1,Jornada&Equipo_local,0)),INDEX(Equipo_local,MATCH($BH4&CR$1,Jornada&Equipo_visitante,0)))} -> Liverpool
A5: 1 | B5: =Horarios!C5 -> 46273.875 | C5: =Horarios!C5 -> 46273.875 | D5: Porto | E5: {=badge_home} -> #VALUE! | J5: {=badge_away} -> #VALUE! | K5: Manchester City | N5: 4 | O5: {=badge_away} -> #VALUE! | P5: =IFERROR(INDEX(Calcs!A$2:A$37,MATCH($N5,Calcs!$CJ$2:$CJ$37,0)),"") -> Atlético Madrid | Q5: =IFERROR(INDEX(Calcs!$B$2:$AB$37,MATCH($N5,Calcs!$CJ$2:$CJ$37,0),MATCH(Q$1,Calcs!$B$1:$AB$1,0)),"") -> 0 | R5: =IFERROR(INDEX(Calcs!$B$2:$AB$37,MATCH($N5,Calcs!$CJ$2:$CJ$37,0),MATCH(R$1,Calcs!$B$1:$AB$1,0)),"") -> 0 | S5: =IFERROR(INDEX(Calcs!$B$2:$AB$37,MATCH($N5,Calcs!$CJ$2:$CJ$37,0),MATCH(S$1,Calcs!$B$1:$AB$1,0)),"") -> 0 | T5: =IFERROR(INDEX(Calcs!$B$2:$AB$37,MATCH($N5,Calcs!$CJ$2:$CJ$37,0),MATCH(T$1,Calcs!$B$1:$AB$1,0)),"") -> 0 | U5: =IFERROR(INDEX(Calcs!$B$2:$AB$37,MATCH($N5,Calcs!$CJ$2:$CJ$37,0),MATCH(U$1,Calcs!$B$1:$AB$1,0)),"") -> 0 | V5: =IFERROR(INDEX(Calcs!$B$2:$AB$37,MATCH($N5,Calcs!$CJ$2:$CJ$37,0),MATCH(V$1,Calcs!$B$1:$AB$1,0)),"") -> 0 | W5: =IFERROR(INDEX(Calcs!$B$2:$AB$37,MATCH($N5,Calcs!$CJ$2:$CJ$37,0),MATCH(W$1,Calcs!$B$1:$AB$1,0)),"") -> 0 | X5: =IFERROR(INDEX(Calcs!$B$2:$AB$37,MATCH($N5,Calcs!$CJ$2:$CJ$37,0),MATCH(X$1,Calcs!$B$1:$AB$1,0)),"") -> 0 | ... AQ5: =IFERROR(INDEX(Calcs!$B$2:$AB$37,MATCH($N5,Calcs!$CJ$2:$CJ$37,0),MATCH(AQ$1,Calcs!$B$1:$AB$1,0)),"") -> 0 | AS5: =INDEX(Calcs!A$2:A$37,MATCH($N5,Calcs!$CF$2:$CF$37,0)) -> Atlético Madrid | AU5: =INDEX(Calcs!$BZ$2:$BZ$37,MATCH($AS5,Calcs!$A$2:$A$37,0)) -> 1 | AV5: =COUNTIF($AU$2:$AU$37,$AU5) -> 36 | AW5: =AU5&"."&AV5 -> 1.36 | AX5: 4 | AZ5: =TablaEquipos[[#This Row],[Team]] -> Atlético Madrid | BF5: =IF(OR(G5="",H5=""),"Pendiente",IF(G5>H5,"Local",IF(G5<H5,"Visitante","Empate"))) -> Pendiente | BH5: 4 | BI5: {=IFERROR(INDEX(Equipo_visitante,MATCH($BH5&BI$1,Jornada&Equipo_local,0)),INDEX(Equipo_local,MATCH($BH5&BI$1,Jornada&Equipo_visitante,0)))} -> Real Madrid | BJ5: {=IFERROR(INDEX(Equipo_visitante,MATCH($BH5&BJ$1,Jornada&Equipo_local,0)),INDEX(Equipo_local,MATCH($BH5&BJ$1,Jornada&Equipo_visitante,0)))} -> Slavia Praha | BK5: {=IFERROR(INDEX(Equipo_visitante,MATCH($BH5&BK$1,Jornada&Equipo_local,0)),INDEX(Equipo_local,MATCH($BH5&BK$1,Jornada&Equipo_visitante,0)))} -> Barcelona | BL5: {=IFERROR(INDEX(Equipo_visitante,MATCH($BH5&BL$1,Jornada&Equipo_local,0)),INDEX(Equipo_local,MATCH($BH5&BL$1,Jornada&Equipo_visitante,0)))} -> Bayern München | BM5: {=IFERROR(INDEX(Equipo_visitante,MATCH($BH5&BM$1,Jornada&Equipo_local,0)),INDEX(Equipo_local,MATCH($BH5&BM$1,Jornada&Equipo_visitante,0)))} -> Aston Villa | BN5: {=IFERROR(INDEX(Equipo_visitante,MATCH($BH5&BN$1,Jornada&Equipo_local,0)),INDEX(Equipo_local,MATCH($BH5&BN$1,Jornada&Equipo_visitante,0)))} -> Atlético Madrid | BO5: {=IFERROR(INDEX(Equipo_visitante,MATCH($BH5&BO$1,Jornada&Equipo_local,0)),INDEX(Equipo_local,MATCH($BH5&BO$1,Jornada&Equipo_visitante,0)))} -> Borussia Dortmund | BP5: {=IFERROR(INDEX(Equipo_visitante,MATCH($BH5&BP$1,Jornada&Equipo_local,0)),INDEX(Equipo_local,MATCH($BH5&BP$1,Jornada&Equipo_visitante,0)))} -> Lille | ... CR5: {=IFERROR(INDEX(Equipo_visitante,MATCH($BH5&CR$1,Jornada&Equipo_local,0)),INDEX(Equipo_local,MATCH($BH5&CR$1,Jornada&Equipo_visitante,0)))} -> PSG
A6: 1 | B6: =Horarios!C6 -> 46273.875 | C6: =Horarios!C6 -> 46273.875 | D6: Lille | E6: {=badge_home} -> #VALUE! | J6: {=badge_away} -> #VALUE! | K6: Betis | N6: 5 | O6: {=badge_away} -> #VALUE! | P6: =IFERROR(INDEX(Calcs!A$2:A$37,MATCH($N6,Calcs!$CJ$2:$CJ$37,0)),"") -> Barcelona | Q6: =IFERROR(INDEX(Calcs!$B$2:$AB$37,MATCH($N6,Calcs!$CJ$2:$CJ$37,0),MATCH(Q$1,Calcs!$B$1:$AB$1,0)),"") -> 0 | R6: =IFERROR(INDEX(Calcs!$B$2:$AB$37,MATCH($N6,Calcs!$CJ$2:$CJ$37,0),MATCH(R$1,Calcs!$B$1:$AB$1,0)),"") -> 0 | S6: =IFERROR(INDEX(Calcs!$B$2:$AB$37,MATCH($N6,Calcs!$CJ$2:$CJ$37,0),MATCH(S$1,Calcs!$B$1:$AB$1,0)),"") -> 0 | T6: =IFERROR(INDEX(Calcs!$B$2:$AB$37,MATCH($N6,Calcs!$CJ$2:$CJ$37,0),MATCH(T$1,Calcs!$B$1:$AB$1,0)),"") -> 0 | U6: =IFERROR(INDEX(Calcs!$B$2:$AB$37,MATCH($N6,Calcs!$CJ$2:$CJ$37,0),MATCH(U$1,Calcs!$B$1:$AB$1,0)),"") -> 0 | V6: =IFERROR(INDEX(Calcs!$B$2:$AB$37,MATCH($N6,Calcs!$CJ$2:$CJ$37,0),MATCH(V$1,Calcs!$B$1:$AB$1,0)),"") -> 0 | W6: =IFERROR(INDEX(Calcs!$B$2:$AB$37,MATCH($N6,Calcs!$CJ$2:$CJ$37,0),MATCH(W$1,Calcs!$B$1:$AB$1,0)),"") -> 0 | X6: =IFERROR(INDEX(Calcs!$B$2:$AB$37,MATCH($N6,Calcs!$CJ$2:$CJ$37,0),MATCH(X$1,Calcs!$B$1:$AB$1,0)),"") -> 0 | ... AQ6: =IFERROR(INDEX(Calcs!$B$2:$AB$37,MATCH($N6,Calcs!$CJ$2:$CJ$37,0),MATCH(AQ$1,Calcs!$B$1:$AB$1,0)),"") -> 0 | AS6: =INDEX(Calcs!A$2:A$37,MATCH($N6,Calcs!$CF$2:$CF$37,0)) -> Barcelona | AU6: =INDEX(Calcs!$BZ$2:$BZ$37,MATCH($AS6,Calcs!$A$2:$A$37,0)) -> 1 | AV6: =COUNTIF($AU$2:$AU$37,$AU6) -> 36 | AW6: =AU6&"."&AV6 -> 1.36 | AX6: 5 | AZ6: =TablaEquipos[[#This Row],[Team]] -> Barcelona | BF6: =IF(OR(G6="",H6=""),"Pendiente",IF(G6>H6,"Local",IF(G6<H6,"Visitante","Empate"))) -> Pendiente | BG6: {=IFERROR(INDEX(Equipo_visitante,SMALL(IF(BI$1=Equipo_local,ROW(Equipo_visitante)-MIN(ROW(Equipo_local))+1,""),ROW()-5)),"")} -> LASK | BH6: 5 | BI6: {=IFERROR(INDEX(Equipo_visitante,MATCH($BH6&BI$1,Jornada&Equipo_local,0)),INDEX(Equipo_local,MATCH($BH6&BI$1,Jornada&Equipo_visitante,0)))} -> Como | BJ6: {=IFERROR(INDEX(Equipo_visitante,MATCH($BH6&BJ$1,Jornada&Equipo_local,0)),INDEX(Equipo_local,MATCH($BH6&BJ$1,Jornada&Equipo_visitante,0)))} -> Borussia Dortmund | BK6: {=IFERROR(INDEX(Equipo_visitante,MATCH($BH6&BK$1,Jornada&Equipo_local,0)),INDEX(Equipo_local,MATCH($BH6&BK$1,Jornada&Equipo_visitante,0)))} -> Galatasaray | BL6: {=IFERROR(INDEX(Equipo_visitante,MATCH($BH6&BL$1,Jornada&Equipo_local,0)),INDEX(Equipo_local,MATCH($BH6&BL$1,Jornada&Equipo_visitante,0)))} -> Viking | BM6: {=IFERROR(INDEX(Equipo_visitante,MATCH($BH6&BM$1,Jornada&Equipo_local,0)),INDEX(Equipo_local,MATCH($BH6&BM$1,Jornada&Equipo_visitante,0)))} -> Sabah | BN6: {=IFERROR(INDEX(Equipo_visitante,MATCH($BH6&BN$1,Jornada&Equipo_local,0)),INDEX(Equipo_local,MATCH($BH6&BN$1,Jornada&Equipo_visitante,0)))} -> Lille | BO6: {=IFERROR(INDEX(Equipo_visitante,MATCH($BH6&BO$1,Jornada&Equipo_local,0)),INDEX(Equipo_local,MATCH($BH6&BO$1,Jornada&Equipo_visitante,0)))} -> Slovan Bratislava | BP6: {=IFERROR(INDEX(Equipo_visitante,MATCH($BH6&BP$1,Jornada&Equipo_local,0)),INDEX(Equipo_local,MATCH($BH6&BP$1,Jornada&Equipo_visitante,0)))} -> LASK | ... CR6: {=IFERROR(INDEX(Equipo_visitante,MATCH($BH6&CR$1,Jornada&Equipo_local,0)),INDEX(Equipo_local,MATCH($BH6&CR$1,Jornada&Equipo_visitante,0)))} -> Slavia Praha
A7: 1 | B7: =Horarios!C7 -> 46273.875 | C7: =Horarios!C7 -> 46273.875 | D7: Real Madrid | E7: {=badge_home} -> #VALUE! | J7: {=badge_away} -> #VALUE! | K7: Inter Milan | N7: 6 | O7: {=badge_away} -> #VALUE! | P7: =IFERROR(INDEX(Calcs!A$2:A$37,MATCH($N7,Calcs!$CJ$2:$CJ$37,0)),"") -> Bayern München | Q7: =IFERROR(INDEX(Calcs!$B$2:$AB$37,MATCH($N7,Calcs!$CJ$2:$CJ$37,0),MATCH(Q$1,Calcs!$B$1:$AB$1,0)),"") -> 0 | R7: =IFERROR(INDEX(Calcs!$B$2:$AB$37,MATCH($N7,Calcs!$CJ$2:$CJ$37,0),MATCH(R$1,Calcs!$B$1:$AB$1,0)),"") -> 0 | S7: =IFERROR(INDEX(Calcs!$B$2:$AB$37,MATCH($N7,Calcs!$CJ$2:$CJ$37,0),MATCH(S$1,Calcs!$B$1:$AB$1,0)),"") -> 0 | T7: =IFERROR(INDEX(Calcs!$B$2:$AB$37,MATCH($N7,Calcs!$CJ$2:$CJ$37,0),MATCH(T$1,Calcs!$B$1:$AB$1,0)),"") -> 0 | U7: =IFERROR(INDEX(Calcs!$B$2:$AB$37,MATCH($N7,Calcs!$CJ$2:$CJ$37,0),MATCH(U$1,Calcs!$B$1:$AB$1,0)),"") -> 0 | V7: =IFERROR(INDEX(Calcs!$B$2:$AB$37,MATCH($N7,Calcs!$CJ$2:$CJ$37,0),MATCH(V$1,Calcs!$B$1:$AB$1,0)),"") -> 0 | W7: =IFERROR(INDEX(Calcs!$B$2:$AB$37,MATCH($N7,Calcs!$CJ$2:$CJ$37,0),MATCH(W$1,Calcs!$B$1:$AB$1,0)),"") -> 0 | X7: =IFERROR(INDEX(Calcs!$B$2:$AB$37,MATCH($N7,Calcs!$CJ$2:$CJ$37,0),MATCH(X$1,Calcs!$B$1:$AB$1,0)),"") -> 0 | ... AQ7: =IFERROR(INDEX(Calcs!$B$2:$AB$37,MATCH($N7,Calcs!$CJ$2:$CJ$37,0),MATCH(AQ$1,Calcs!$B$1:$AB$1,0)),"") -> 0 | AS7: =INDEX(Calcs!A$2:A$37,MATCH($N7,Calcs!$CF$2:$CF$37,0)) -> Bayern München | AU7: =INDEX(Calcs!$BZ$2:$BZ$37,MATCH($AS7,Calcs!$A$2:$A$37,0)) -> 1 | AV7: =COUNTIF($AU$2:$AU$37,$AU7) -> 36 | AW7: =AU7&"."&AV7 -> 1.36 | AX7: 6 | AZ7: =TablaEquipos[[#This Row],[Team]] -> Bayern München | BF7: =IF(OR(G7="",H7=""),"Pendiente",IF(G7>H7,"Local",IF(G7<H7,"Visitante","Empate"))) -> Pendiente | BH7: 6 | BI7: {=IFERROR(INDEX(Equipo_visitante,MATCH($BH7&BI$1,Jornada&Equipo_local,0)),INDEX(Equipo_local,MATCH($BH7&BI$1,Jornada&Equipo_visitante,0)))} -> Galatasaray | BJ7: {=IFERROR(INDEX(Equipo_visitante,MATCH($BH7&BJ$1,Jornada&Equipo_local,0)),INDEX(Equipo_local,MATCH($BH7&BJ$1,Jornada&Equipo_visitante,0)))} -> Real Madrid | BK7: {=IFERROR(INDEX(Equipo_visitante,MATCH($BH7&BK$1,Jornada&Equipo_local,0)),INDEX(Equipo_local,MATCH($BH7&BK$1,Jornada&Equipo_visitante,0)))} -> PSG | BL7: {=IFERROR(INDEX(Equipo_visitante,MATCH($BH7&BL$1,Jornada&Equipo_local,0)),INDEX(Equipo_local,MATCH($BH7&BL$1,Jornada&Equipo_visitante,0)))} -> PSV Eindhoven | BM7: {=IFERROR(INDEX(Equipo_visitante,MATCH($BH7&BM$1,Jornada&Equipo_local,0)),INDEX(Equipo_local,MATCH($BH7&BM$1,Jornada&Equipo_visitante,0)))} -> Manchester City | BN7: {=IFERROR(INDEX(Equipo_visitante,MATCH($BH7&BN$1,Jornada&Equipo_local,0)),INDEX(Equipo_local,MATCH($BH7&BN$1,Jornada&Equipo_visitante,0)))} -> Slavia Praha | BO7: {=IFERROR(INDEX(Equipo_visitante,MATCH($BH7&BO$1,Jornada&Equipo_local,0)),INDEX(Equipo_local,MATCH($BH7&BO$1,Jornada&Equipo_visitante,0)))} -> Como | BP7: {=IFERROR(INDEX(Equipo_visitante,MATCH($BH7&BP$1,Jornada&Equipo_local,0)),INDEX(Equipo_local,MATCH($BH7&BP$1,Jornada&Equipo_visitante,0)))} -> Lens | ... CR7: {=IFERROR(INDEX(Equipo_visitante,MATCH($BH7&CR$1,Jornada&Equipo_local,0)),INDEX(Equipo_local,MATCH($BH7&CR$1,Jornada&Equipo_visitante,0)))} -> Sabah
A8: 1 | B8: =Horarios!C8 -> 46274.781 | C8: =Horarios!C8 -> 46274.781 | D8: Barcelona | E8: {=badge_home} -> #VALUE! | J8: {=badge_away} -> #VALUE! | K8: Feyenoord | N8: 7 | O8: {=badge_away} -> #VALUE! | P8: =IFERROR(INDEX(Calcs!A$2:A$37,MATCH($N8,Calcs!$CJ$2:$CJ$37,0)),"") -> Betis | Q8: =IFERROR(INDEX(Calcs!$B$2:$AB$37,MATCH($N8,Calcs!$CJ$2:$CJ$37,0),MATCH(Q$1,Calcs!$B$1:$AB$1,0)),"") -> 0 | R8: =IFERROR(INDEX(Calcs!$B$2:$AB$37,MATCH($N8,Calcs!$CJ$2:$CJ$37,0),MATCH(R$1,Calcs!$B$1:$AB$1,0)),"") -> 0 | S8: =IFERROR(INDEX(Calcs!$B$2:$AB$37,MATCH($N8,Calcs!$CJ$2:$CJ$37,0),MATCH(S$1,Calcs!$B$1:$AB$1,0)),"") -> 0 | T8: =IFERROR(INDEX(Calcs!$B$2:$AB$37,MATCH($N8,Calcs!$CJ$2:$CJ$37,0),MATCH(T$1,Calcs!$B$1:$AB$1,0)),"") -> 0 | U8: =IFERROR(INDEX(Calcs!$B$2:$AB$37,MATCH($N8,Calcs!$CJ$2:$CJ$37,0),MATCH(U$1,Calcs!$B$1:$AB$1,0)),"") -> 0 | V8: =IFERROR(INDEX(Calcs!$B$2:$AB$37,MATCH($N8,Calcs!$CJ$2:$CJ$37,0),MATCH(V$1,Calcs!$B$1:$AB$1,0)),"") -> 0 | W8: =IFERROR(INDEX(Calcs!$B$2:$AB$37,MATCH($N8,Calcs!$CJ$2:$CJ$37,0),MATCH(W$1,Calcs!$B$1:$AB$1,0)),"") -> 0 | X8: =IFERROR(INDEX(Calcs!$B$2:$AB$37,MATCH($N8,Calcs!$CJ$2:$CJ$37,0),MATCH(X$1,Calcs!$B$1:$AB$1,0)),"") -> 0 | ... AQ8: =IFERROR(INDEX(Calcs!$B$2:$AB$37,MATCH($N8,Calcs!$CJ$2:$CJ$37,0),MATCH(AQ$1,Calcs!$B$1:$AB$1,0)),"") -> 0 | AS8: =INDEX(Calcs!A$2:A$37,MATCH($N8,Calcs!$CF$2:$CF$37,0)) -> Betis | AU8: =INDEX(Calcs!$BZ$2:$BZ$37,MATCH($AS8,Calcs!$A$2:$A$37,0)) -> 1 | AV8: =COUNTIF($AU$2:$AU$37,$AU8) -> 36 | AW8: =AU8&"."&AV8 -> 1.36 | AX8: 7 | AZ8: =TablaEquipos[[#This Row],[Team]] -> Betis | BF8: =IF(OR(G8="",H8=""),"Pendiente",IF(G8>H8,"Local",IF(G8<H8,"Visitante","Empate"))) -> Pendiente | BH8: 7 | BI8: {=IFERROR(INDEX(Equipo_visitante,MATCH($BH8&BI$1,Jornada&Equipo_local,0)),INDEX(Equipo_local,MATCH($BH8&BI$1,Jornada&Equipo_visitante,0)))} -> Roma | BJ8: {=IFERROR(INDEX(Equipo_visitante,MATCH($BH8&BJ$1,Jornada&Equipo_local,0)),INDEX(Equipo_local,MATCH($BH8&BJ$1,Jornada&Equipo_visitante,0)))} -> Betis | BK8: {=IFERROR(INDEX(Equipo_visitante,MATCH($BH8&BK$1,Jornada&Equipo_local,0)),INDEX(Equipo_local,MATCH($BH8&BK$1,Jornada&Equipo_visitante,0)))} -> Borussia Dortmund | BL8: {=IFERROR(INDEX(Equipo_visitante,MATCH($BH8&BL$1,Jornada&Equipo_local,0)),INDEX(Equipo_local,MATCH($BH8&BL$1,Jornada&Equipo_visitante,0)))} -> Bodø/Glimt | BM8: {=IFERROR(INDEX(Equipo_visitante,MATCH($BH8&BM$1,Jornada&Equipo_local,0)),INDEX(Equipo_local,MATCH($BH8&BM$1,Jornada&Equipo_visitante,0)))} -> Sporting Portugal | BN8: {=IFERROR(INDEX(Equipo_visitante,MATCH($BH8&BN$1,Jornada&Equipo_local,0)),INDEX(Equipo_local,MATCH($BH8&BN$1,Jornada&Equipo_visitante,0)))} -> Manchester United | BO8: {=IFERROR(INDEX(Equipo_visitante,MATCH($BH8&BO$1,Jornada&Equipo_local,0)),INDEX(Equipo_local,MATCH($BH8&BO$1,Jornada&Equipo_visitante,0)))} -> Arsenal | BP8: {=IFERROR(INDEX(Equipo_visitante,MATCH($BH8&BP$1,Jornada&Equipo_local,0)),INDEX(Equipo_local,MATCH($BH8&BP$1,Jornada&Equipo_visitante,0)))} -> Atlético Madrid | ... CR8: {=IFERROR(INDEX(Equipo_visitante,MATCH($BH8&CR$1,Jornada&Equipo_local,0)),INDEX(Equipo_local,MATCH($BH8&CR$1,Jornada&Equipo_visitante,0)))} -> Fenerbahçe
A9: 1 | B9: =Horarios!C9 -> 46274.781 | C9: =Horarios!C9 -> 46274.781 | D9: Stuttgart | E9: {=badge_home} -> #VALUE! | J9: {=badge_away} -> #VALUE! | K9: Viking | N9: 8 | O9: {=badge_away} -> #VALUE! | P9: =IFERROR(INDEX(Calcs!A$2:A$37,MATCH($N9,Calcs!$CJ$2:$CJ$37,0)),"") -> Bodø/Glimt | Q9: =IFERROR(INDEX(Calcs!$B$2:$AB$37,MATCH($N9,Calcs!$CJ$2:$CJ$37,0),MATCH(Q$1,Calcs!$B$1:$AB$1,0)),"") -> 0 | R9: =IFERROR(INDEX(Calcs!$B$2:$AB$37,MATCH($N9,Calcs!$CJ$2:$CJ$37,0),MATCH(R$1,Calcs!$B$1:$AB$1,0)),"") -> 0 | S9: =IFERROR(INDEX(Calcs!$B$2:$AB$37,MATCH($N9,Calcs!$CJ$2:$CJ$37,0),MATCH(S$1,Calcs!$B$1:$AB$1,0)),"") -> 0 | T9: =IFERROR(INDEX(Calcs!$B$2:$AB$37,MATCH($N9,Calcs!$CJ$2:$CJ$37,0),MATCH(T$1,Calcs!$B$1:$AB$1,0)),"") -> 0 | U9: =IFERROR(INDEX(Calcs!$B$2:$AB$37,MATCH($N9,Calcs!$CJ$2:$CJ$37,0),MATCH(U$1,Calcs!$B$1:$AB$1,0)),"") -> 0 | V9: =IFERROR(INDEX(Calcs!$B$2:$AB$37,MATCH($N9,Calcs!$CJ$2:$CJ$37,0),MATCH(V$1,Calcs!$B$1:$AB$1,0)),"") -> 0 | W9: =IFERROR(INDEX(Calcs!$B$2:$AB$37,MATCH($N9,Calcs!$CJ$2:$CJ$37,0),MATCH(W$1,Calcs!$B$1:$AB$1,0)),"") -> 0 | X9: =IFERROR(INDEX(Calcs!$B$2:$AB$37,MATCH($N9,Calcs!$CJ$2:$CJ$37,0),MATCH(X$1,Calcs!$B$1:$AB$1,0)),"") -> 0 | ... AQ9: =IFERROR(INDEX(Calcs!$B$2:$AB$37,MATCH($N9,Calcs!$CJ$2:$CJ$37,0),MATCH(AQ$1,Calcs!$B$1:$AB$1,0)),"") -> 0 | AS9: =INDEX(Calcs!A$2:A$37,MATCH($N9,Calcs!$CF$2:$CF$37,0)) -> Bodø/Glimt | AU9: =INDEX(Calcs!$BZ$2:$BZ$37,MATCH($AS9,Calcs!$A$2:$A$37,0)) -> 1 | AV9: =COUNTIF($AU$2:$AU$37,$AU9) -> 36 | AW9: =AU9&"."&AV9 -> 1.36 | AX9: 8 | AZ9: =TablaEquipos[[#This Row],[Team]] -> Bodø/Glimt | BF9: =IF(OR(G9="",H9=""),"Pendiente",IF(G9>H9,"Local",IF(G9<H9,"Visitante","Empate"))) -> Pendiente | BH9: 8 | BI9: {=IFERROR(INDEX(Equipo_visitante,MATCH($BH9&BI$1,Jornada&Equipo_local,0)),INDEX(Equipo_local,MATCH($BH9&BI$1,Jornada&Equipo_visitante,0)))} -> Borussia Dortmund | BJ9: {=IFERROR(INDEX(Equipo_visitante,MATCH($BH9&BJ$1,Jornada&Equipo_local,0)),INDEX(Equipo_local,MATCH($BH9&BJ$1,Jornada&Equipo_visitante,0)))} -> Sabah | BK9: {=IFERROR(INDEX(Equipo_visitante,MATCH($BH9&BK$1,Jornada&Equipo_local,0)),INDEX(Equipo_local,MATCH($BH9&BK$1,Jornada&Equipo_visitante,0)))} -> Slavia Praha | BL9: {=IFERROR(INDEX(Equipo_visitante,MATCH($BH9&BL$1,Jornada&Equipo_local,0)),INDEX(Equipo_local,MATCH($BH9&BL$1,Jornada&Equipo_visitante,0)))} -> Fenerbahçe | BM9: {=IFERROR(INDEX(Equipo_visitante,MATCH($BH9&BM$1,Jornada&Equipo_local,0)),INDEX(Equipo_local,MATCH($BH9&BM$1,Jornada&Equipo_visitante,0)))} -> Como | BN9: {=IFERROR(INDEX(Equipo_visitante,MATCH($BH9&BN$1,Jornada&Equipo_local,0)),INDEX(Equipo_local,MATCH($BH9&BN$1,Jornada&Equipo_visitante,0)))} -> Betis | BO9: {=IFERROR(INDEX(Equipo_visitante,MATCH($BH9&BO$1,Jornada&Equipo_local,0)),INDEX(Equipo_local,MATCH($BH9&BO$1,Jornada&Equipo_visitante,0)))} -> Bayern München | BP9: {=IFERROR(INDEX(Equipo_visitante,MATCH($BH9&BP$1,Jornada&Equipo_local,0)),INDEX(Equipo_local,MATCH($BH9&BP$1,Jornada&Equipo_visitante,0)))} -> Brugge | ... CR9: {=IFERROR(INDEX(Equipo_visitante,MATCH($BH9&CR$1,Jornada&Equipo_local,0)),INDEX(Equipo_local,MATCH($BH9&CR$1,Jornada&Equipo_visitante,0)))} -> Manchester United
A10: 1 | B10: =Horarios!C10 -> 46274.875 | C10: =Horarios!C10 -> 46274.875 | D10: Liverpool | E10: {=badge_home} -> #VALUE! | J10: {=badge_away} -> #VALUE! | K10: Atlético Madrid | N10: 9 | O10: {=badge_away} -> #VALUE! | P10: =IFERROR(INDEX(Calcs!A$2:A$37,MATCH($N10,Calcs!$CJ$2:$CJ$37,0)),"") -> Borussia Dortmund | Q10: =IFERROR(INDEX(Calcs!$B$2:$AB$37,MATCH($N10,Calcs!$CJ$2:$CJ$37,0),MATCH(Q$1,Calcs!$B$1:$AB$1,0)),"") -> 0 | R10: =IFERROR(INDEX(Calcs!$B$2:$AB$37,MATCH($N10,Calcs!$CJ$2:$CJ$37,0),MATCH(R$1,Calcs!$B$1:$AB$1,0)),"") -> 0 | S10: =IFERROR(INDEX(Calcs!$B$2:$AB$37,MATCH($N10,Calcs!$CJ$2:$CJ$37,0),MATCH(S$1,Calcs!$B$1:$AB$1,0)),"") -> 0 | T10: =IFERROR(INDEX(Calcs!$B$2:$AB$37,MATCH($N10,Calcs!$CJ$2:$CJ$37,0),MATCH(T$1,Calcs!$B$1:$AB$1,0)),"") -> 0 | U10: =IFERROR(INDEX(Calcs!$B$2:$AB$37,MATCH($N10,Calcs!$CJ$2:$CJ$37,0),MATCH(U$1,Calcs!$B$1:$AB$1,0)),"") -> 0 | V10: =IFERROR(INDEX(Calcs!$B$2:$AB$37,MATCH($N10,Calcs!$CJ$2:$CJ$37,0),MATCH(V$1,Calcs!$B$1:$AB$1,0)),"") -> 0 | W10: =IFERROR(INDEX(Calcs!$B$2:$AB$37,MATCH($N10,Calcs!$CJ$2:$CJ$37,0),MATCH(W$1,Calcs!$B$1:$AB$1,0)),"") -> 0 | X10: =IFERROR(INDEX(Calcs!$B$2:$AB$37,MATCH($N10,Calcs!$CJ$2:$CJ$37,0),MATCH(X$1,Calcs!$B$1:$AB$1,0)),"") -> 0 | ... AQ10: =IFERROR(INDEX(Calcs!$B$2:$AB$37,MATCH($N10,Calcs!$CJ$2:$CJ$37,0),MATCH(AQ$1,Calcs!$B$1:$AB$1,0)),"") -> 0 | AS10: =INDEX(Calcs!A$2:A$37,MATCH($N10,Calcs!$CF$2:$CF$37,0)) -> Borussia Dortmund | AU10: =INDEX(Calcs!$BZ$2:$BZ$37,MATCH($AS10,Calcs!$A$2:$A$37,0)) -> 1 | AV10: =COUNTIF($AU$2:$AU$37,$AU10) -> 36 | AW10: =AU10&"."&AV10 -> 1.36 | AX10: 9 | AZ10: =TablaEquipos[[#This Row],[Team]] -> Borussia Dortmund | BF10: =IF(OR(G10="",H10=""),"Pendiente",IF(G10>H10,"Local",IF(G10<H10,"Visitante","Empate"))) -> Pendiente | BH10: Puntos | BI10: =SUMIF(Calcs!$A$2:$A$37,League!BI2,Calcs!$I$2:$I$37)-INDEX($BA$2:$BA$37,MATCH(BI2,$AZ$2:$AZ$37,0)) -> 0 | BJ10: =SUMIF(Calcs!$A$2:$A$37,League!BJ2,Calcs!$I$2:$I$37)-INDEX($BA$2:$BA$37,MATCH(BJ2,$AZ$2:$AZ$37,0)) -> 0 | BK10: =SUMIF(Calcs!$A$2:$A$37,League!BK2,Calcs!$I$2:$I$37)-INDEX($BA$2:$BA$37,MATCH(BK2,$AZ$2:$AZ$37,0)) -> 0 | BL10: =SUMIF(Calcs!$A$2:$A$37,League!BL2,Calcs!$I$2:$I$37)-INDEX($BA$2:$BA$37,MATCH(BL2,$AZ$2:$AZ$37,0)) -> 0 | BM10: =SUMIF(Calcs!$A$2:$A$37,League!BM2,Calcs!$I$2:$I$37)-INDEX($BA$2:$BA$37,MATCH(BM2,$AZ$2:$AZ$37,0)) -> 0 | BN10: =SUMIF(Calcs!$A$2:$A$37,League!BN2,Calcs!$I$2:$I$37)-INDEX($BA$2:$BA$37,MATCH(BN2,$AZ$2:$AZ$37,0)) -> 0 | BO10: =SUMIF(Calcs!$A$2:$A$37,League!BO2,Calcs!$I$2:$I$37)-INDEX($BA$2:$BA$37,MATCH(BO2,$AZ$2:$AZ$37,0)) -> 0 | BP10: =SUMIF(Calcs!$A$2:$A$37,League!BP2,Calcs!$I$2:$I$37)-INDEX($BA$2:$BA$37,MATCH(BP2,$AZ$2:$AZ$37,0)) -> 0 | ... CR10: =SUMIF(Calcs!$A$2:$A$37,League!CR2,Calcs!$I$2:$I$37)-INDEX($BA$2:$BA$37,MATCH(CR2,$AZ$2:$AZ$37,0)) -> 0
A11: 1 | B11: =Horarios!C11 -> 46274.875 | C11: =Horarios!C11 -> 46274.875 | D11: PSG | E11: {=badge_home} -> #VALUE! | J11: {=badge_away} -> #VALUE! | K11: Slovan Bratislava | N11: 10 | O11: {=badge_away} -> #VALUE! | P11: =IFERROR(INDEX(Calcs!A$2:A$37,MATCH($N11,Calcs!$CJ$2:$CJ$37,0)),"") -> Brugge | Q11: =IFERROR(INDEX(Calcs!$B$2:$AB$37,MATCH($N11,Calcs!$CJ$2:$CJ$37,0),MATCH(Q$1,Calcs!$B$1:$AB$1,0)),"") -> 0 | R11: =IFERROR(INDEX(Calcs!$B$2:$AB$37,MATCH($N11,Calcs!$CJ$2:$CJ$37,0),MATCH(R$1,Calcs!$B$1:$AB$1,0)),"") -> 0 | S11: =IFERROR(INDEX(Calcs!$B$2:$AB$37,MATCH($N11,Calcs!$CJ$2:$CJ$37,0),MATCH(S$1,Calcs!$B$1:$AB$1,0)),"") -> 0 | T11: =IFERROR(INDEX(Calcs!$B$2:$AB$37,MATCH($N11,Calcs!$CJ$2:$CJ$37,0),MATCH(T$1,Calcs!$B$1:$AB$1,0)),"") -> 0 | U11: =IFERROR(INDEX(Calcs!$B$2:$AB$37,MATCH($N11,Calcs!$CJ$2:$CJ$37,0),MATCH(U$1,Calcs!$B$1:$AB$1,0)),"") -> 0 | V11: =IFERROR(INDEX(Calcs!$B$2:$AB$37,MATCH($N11,Calcs!$CJ$2:$CJ$37,0),MATCH(V$1,Calcs!$B$1:$AB$1,0)),"") -> 0 | W11: =IFERROR(INDEX(Calcs!$B$2:$AB$37,MATCH($N11,Calcs!$CJ$2:$CJ$37,0),MATCH(W$1,Calcs!$B$1:$AB$1,0)),"") -> 0 | X11: =IFERROR(INDEX(Calcs!$B$2:$AB$37,MATCH($N11,Calcs!$CJ$2:$CJ$37,0),MATCH(X$1,Calcs!$B$1:$AB$1,0)),"") -> 0 | ... AQ11: =IFERROR(INDEX(Calcs!$B$2:$AB$37,MATCH($N11,Calcs!$CJ$2:$CJ$37,0),MATCH(AQ$1,Calcs!$B$1:$AB$1,0)),"") -> 0 | AS11: =INDEX(Calcs!A$2:A$37,MATCH($N11,Calcs!$CF$2:$CF$37,0)) -> Brugge | AU11: =INDEX(Calcs!$BZ$2:$BZ$37,MATCH($AS11,Calcs!$A$2:$A$37,0)) -> 1 | AV11: =COUNTIF($AU$2:$AU$37,$AU11) -> 36 | AW11: =AU11&"."&AV11 -> 1.36 | AX11: 10 | AZ11: =TablaEquipos[[#This Row],[Team]] -> Brugge | BF11: =IF(OR(G11="",H11=""),"Pendiente",IF(G11>H11,"Local",IF(G11<H11,"Visitante","Empate"))) -> Pendiente | BI11: =SUMIF(Calcs!$A$2:$A$37,League!BI3,Calcs!$I$2:$I$37)-INDEX($BA$2:$BA$37,MATCH(BI3,$AZ$2:$AZ$37,0)) -> 0 | BJ11: =SUMIF(Calcs!$A$2:$A$37,League!BJ3,Calcs!$I$2:$I$37)-INDEX($BA$2:$BA$37,MATCH(BJ3,$AZ$2:$AZ$37,0)) -> 0 | BK11: =SUMIF(Calcs!$A$2:$A$37,League!BK3,Calcs!$I$2:$I$37)-INDEX($BA$2:$BA$37,MATCH(BK3,$AZ$2:$AZ$37,0)) -> 0 | BL11: =SUMIF(Calcs!$A$2:$A$37,League!BL3,Calcs!$I$2:$I$37)-INDEX($BA$2:$BA$37,MATCH(BL3,$AZ$2:$AZ$37,0)) -> 0 | BM11: =SUMIF(Calcs!$A$2:$A$37,League!BM3,Calcs!$I$2:$I$37)-INDEX($BA$2:$BA$37,MATCH(BM3,$AZ$2:$AZ$37,0)) -> 0 | BN11: =SUMIF(Calcs!$A$2:$A$37,League!BN3,Calcs!$I$2:$I$37)-INDEX($BA$2:$BA$37,MATCH(BN3,$AZ$2:$AZ$37,0)) -> 0 | BO11: =SUMIF(Calcs!$A$2:$A$37,League!BO3,Calcs!$I$2:$I$37)-INDEX($BA$2:$BA$37,MATCH(BO3,$AZ$2:$AZ$37,0)) -> 0 | BP11: =SUMIF(Calcs!$A$2:$A$37,League!BP3,Calcs!$I$2:$I$37)-INDEX($BA$2:$BA$37,MATCH(BP3,$AZ$2:$AZ$37,0)) -> 0 | ... CR11: =SUMIF(Calcs!$A$2:$A$37,League!CR3,Calcs!$I$2:$I$37)-INDEX($BA$2:$BA$37,MATCH(CR3,$AZ$2:$AZ$37,0)) -> 0
A12: 1 | B12: =Horarios!C12 -> 46274.875 | C12: =Horarios!C12 -> 46274.875 | D12: Sporting Portugal | E12: {=badge_home} -> #VALUE! | J12: {=badge_away} -> #VALUE! | K12: Galatasaray | N12: 11 | O12: {=badge_away} -> #VALUE! | P12: =IFERROR(INDEX(Calcs!A$2:A$37,MATCH($N12,Calcs!$CJ$2:$CJ$37,0)),"") -> Como | Q12: =IFERROR(INDEX(Calcs!$B$2:$AB$37,MATCH($N12,Calcs!$CJ$2:$CJ$37,0),MATCH(Q$1,Calcs!$B$1:$AB$1,0)),"") -> 0 | R12: =IFERROR(INDEX(Calcs!$B$2:$AB$37,MATCH($N12,Calcs!$CJ$2:$CJ$37,0),MATCH(R$1,Calcs!$B$1:$AB$1,0)),"") -> 0 | S12: =IFERROR(INDEX(Calcs!$B$2:$AB$37,MATCH($N12,Calcs!$CJ$2:$CJ$37,0),MATCH(S$1,Calcs!$B$1:$AB$1,0)),"") -> 0 | T12: =IFERROR(INDEX(Calcs!$B$2:$AB$37,MATCH($N12,Calcs!$CJ$2:$CJ$37,0),MATCH(T$1,Calcs!$B$1:$AB$1,0)),"") -> 0 | U12: =IFERROR(INDEX(Calcs!$B$2:$AB$37,MATCH($N12,Calcs!$CJ$2:$CJ$37,0),MATCH(U$1,Calcs!$B$1:$AB$1,0)),"") -> 0 | V12: =IFERROR(INDEX(Calcs!$B$2:$AB$37,MATCH($N12,Calcs!$CJ$2:$CJ$37,0),MATCH(V$1,Calcs!$B$1:$AB$1,0)),"") -> 0 | W12: =IFERROR(INDEX(Calcs!$B$2:$AB$37,MATCH($N12,Calcs!$CJ$2:$CJ$37,0),MATCH(W$1,Calcs!$B$1:$AB$1,0)),"") -> 0 | X12: =IFERROR(INDEX(Calcs!$B$2:$AB$37,MATCH($N12,Calcs!$CJ$2:$CJ$37,0),MATCH(X$1,Calcs!$B$1:$AB$1,0)),"") -> 0 | ... AQ12: =IFERROR(INDEX(Calcs!$B$2:$AB$37,MATCH($N12,Calcs!$CJ$2:$CJ$37,0),MATCH(AQ$1,Calcs!$B$1:$AB$1,0)),"") -> 0 | AS12: =INDEX(Calcs!A$2:A$37,MATCH($N12,Calcs!$CF$2:$CF$37,0)) -> Como | AU12: =INDEX(Calcs!$BZ$2:$BZ$37,MATCH($AS12,Calcs!$A$2:$A$37,0)) -> 1 | AV12: =COUNTIF($AU$2:$AU$37,$AU12) -> 36 | AW12: =AU12&"."&AV12 -> 1.36 | AX12: 11 | AZ12: =TablaEquipos[[#This Row],[Team]] -> Como | BF12: =IF(OR(G12="",H12=""),"Pendiente",IF(G12>H12,"Local",IF(G12<H12,"Visitante","Empate"))) -> Pendiente | BI12: =SUMIF(Calcs!$A$2:$A$37,League!BI4,Calcs!$I$2:$I$37)-INDEX($BA$2:$BA$37,MATCH(BI4,$AZ$2:$AZ$37,0)) -> 0 | BJ12: =SUMIF(Calcs!$A$2:$A$37,League!BJ4,Calcs!$I$2:$I$37)-INDEX($BA$2:$BA$37,MATCH(BJ4,$AZ$2:$AZ$37,0)) -> 0 | BK12: =SUMIF(Calcs!$A$2:$A$37,League!BK4,Calcs!$I$2:$I$37)-INDEX($BA$2:$BA$37,MATCH(BK4,$AZ$2:$AZ$37,0)) -> 0 | BL12: =SUMIF(Calcs!$A$2:$A$37,League!BL4,Calcs!$I$2:$I$37)-INDEX($BA$2:$BA$37,MATCH(BL4,$AZ$2:$AZ$37,0)) -> 0 | BM12: =SUMIF(Calcs!$A$2:$A$37,League!BM4,Calcs!$I$2:$I$37)-INDEX($BA$2:$BA$37,MATCH(BM4,$AZ$2:$AZ$37,0)) -> 0 | BN12: =SUMIF(Calcs!$A$2:$A$37,League!BN4,Calcs!$I$2:$I$37)-INDEX($BA$2:$BA$37,MATCH(BN4,$AZ$2:$AZ$37,0)) -> 0 | BO12: =SUMIF(Calcs!$A$2:$A$37,League!BO4,Calcs!$I$2:$I$37)-INDEX($BA$2:$BA$37,MATCH(BO4,$AZ$2:$AZ$37,0)) -> 0 | BP12: =SUMIF(Calcs!$A$2:$A$37,League!BP4,Calcs!$I$2:$I$37)-INDEX($BA$2:$BA$37,MATCH(BP4,$AZ$2:$AZ$37,0)) -> 0 | ... CR12: =SUMIF(Calcs!$A$2:$A$37,League!CR4,Calcs!$I$2:$I$37)-INDEX($BA$2:$BA$37,MATCH(CR4,$AZ$2:$AZ$37,0)) -> 0
